Workbook

Sheet Comparison
A1: No. | B1: Group | C1: Topic | D1: Indicator | E1: Survey: households meeting the condition | F1: Survey: households answering | G1: Survey: value | H1: Unit (JD = Jordanian dinars, per month) | I1: Published figure | J1: Whom the published figure covers and when | K1: Source | L1: Same measure? | M1: Difference (points or units) | N1: Survey margin (points) | O1: Reading | P1: Note
A2: 1 | B2: Zaatari camp | C2: Where and who | D2: Origin in Daraa governorate | E2: 211 | F2: 246 | G2: =E2/F2 -> 0.85772358 | H2: % | I2: 0.817 | J2: All households in the camp, January 2015 | K2: REACH 2015 | L2: Yes | M2: =IF(AND(ISNUMBER(G2),ISNUMBER(I2)),IF(H2="%",(G2-I2)*100,G2-I2),"") -> 4.0723577 | N2: =IF(AND(H2="%",ISNUMBER(G2),ISNUMBER(F2)),1.96*SQRT(G2*(1-G2)/F2)*100,"") -> 4.3654464 | O2: =IF(L2="No","Not the same measure",IF(H2="%",IF(ABS(M2)<10,"Close",IF(ABS(M2)<=0.9*N2,"Within the margin",IF(ABS(M2)<=1.1*N2,"At the edge of the margin","Differs"))),IF(ABS(M2)/I2<0.15,"Close","Differs"))) -> Close | P2: The UNHCR factsheet of April 2015 gives another figure (53.4% from Daraa) without saying which population it refers to; the household-by-household count is used.
A3: 2 | B3: Zaatari camp | C3: Where and who | D3: Origin in Damascus or Rif Dimashq | E3: 23 | F3: 246 | G3: =E3/F3 -> 0.093495935 | H3: % | I3: =Calculations!$C$42 -> 0.1527 | J3: All households in the camp, January 2015: Rif Dimashq (14.3%) plus Damascus (1.0%) | K3: REACH 2015 | L3: Yes | M3: =IF(AND(ISNUMBER(G3),ISNUMBER(I3)),IF(H3="%",(G3-I3)*100,G3-I3),"") -> -5.9204065 | N3: =IF(AND(H3="%",ISNUMBER(G3),ISNUMBER(F3)),1.96*SQRT(G3*(1-G3)/F3)*100,"") -> 3.6380592 | O3: =IF(L3="No","Not the same measure",IF(H3="%",IF(ABS(M3)<10,"Close",IF(ABS(M3)<=0.9*N3,"Within the margin",IF(ABS(M3)<=1.1*N3,"At the edge of the margin","Differs"))),IF(ABS(M3)/I3<0.15,"Close","Differs"))) -> Close
A4: 3 | B4: Zaatari camp | C4: Where and who | D4: Distribution across the twelve districts | E4: see sheet | F4: 249 | G4: Largest difference in a district: 3.0 points | H4: text | I4: Households by district, January 2015 | J4: All households in the camp | K4: REACH 2015 | L4: Yes | M4: =IF(AND(ISNUMBER(G4),ISNUMBER(I4)),IF(H4="%",(G4-I4)*100,G4-I4),"") | N4: =IF(AND(H4="%",ISNUMBER(G4),ISNUMBER(F4)),1.96*SQRT(G4*(1-G4)/F4)*100,"") | O4: Close | P4: Chi-square of 10.8 with 11 degrees of freedom, p = 0.46: the two distributions cannot be told apart. The calculation is in the Places and districts sheet.
A5: 4 | B5: Zaatari camp | C5: Where and who | D5: People per household (mean) | F5: 257 | G5: 5 | H5: people | I5: =Calculations!$C$23 -> 5.6068069 | J5: All households in the camp, January 2015: 78,086 people in 13,927 households (the report prints the two totals; the mean is their ratio) | K5: REACH 2015 | L5: Yes | M5: =IF(AND(ISNUMBER(G5),ISNUMBER(I5)),IF(H5="%",(G5-I5)*100,G5-I5),"") -> -0.60680692 | N5: =IF(AND(H5="%",ISNUMBER(G5),ISNUMBER(F5)),1.96*SQRT(G5*(1-G5)/F5)*100,"") | O5: =IF(L5="No","Not the same measure",IF(H5="%",IF(ABS(M5)<10,"Close",IF(ABS(M5)<=0.9*N5,"Within the margin",IF(ABS(M5)<=1.1*N5,"At the edge of the margin","Differs"))),IF(ABS(M5)/I5<0.15,"Close","Differs"))) -> Close | P5: Fafo gives 4.9 people per household in the camps in 2017 and 2018.
A6: 5 | B6: Zaatari camp | C6: Arrival | D6: Arrived in 2012 or earlier | E6: 104 | F6: 234 | G6: =E6/F6 -> 0.44444444 | H6: % | I6: =Calculations!$C$24 -> 0.23 | J6: Arrival in the camp between July and December 2012 (the camp was opened in July 2012) | K6: REACH 2015 | L6: With care | M6: =IF(AND(ISNUMBER(G6),ISNUMBER(I6)),IF(H6="%",(G6-I6)*100,G6-I6),"") -> 21.444444 | N6: =IF(AND(H6="%",ISNUMBER(G6),ISNUMBER(F6)),1.96*SQRT(G6*(1-G6)/F6)*100,"") -> 6.3667915 | O6: =IF(L6="No","Not the same measure",IF(H6="%",IF(ABS(M6)<10,"Close",IF(ABS(M6)<=0.9*N6,"Within the margin",IF(ABS(M6)<=1.1*N6,"At the edge of the margin","Differs"))),IF(ABS(M6)/I6<0.15,"Close","Differs"))) -> Differs | P6: The survey asks the year of arrival in Jordan; the count, arrival in the camp. The year is missing for 23 camp households.
A7: 6 | B7: Zaatari camp | C7: Arrival | D7: Arrived in 2013 | E7: 96 | F7: 234 | G7: =E7/F7 -> 0.41025641 | H7: % | I7: =Calculations!$C$27 -> 0.6 | J7: Arrival in the camp in 2013 (sum of the two half-years the report prints) | K7: REACH 2015 | L7: With care | M7: =IF(AND(ISNUMBER(G7),ISNUMBER(I7)),IF(H7="%",(G7-I7)*100,G7-I7),"") -> -18.974359 | N7: =IF(AND(H7="%",ISNUMBER(G7),ISNUMBER(F7)),1.96*SQRT(G7*(1-G7)/F7)*100,"") -> 6.3024215 | O7: =IF(L7="No","Not the same measure",IF(H7="%",IF(ABS(M7)<10,"Close",IF(ABS(M7)<=0.9*N7,"Within the margin",IF(ABS(M7)<=1.1*N7,"At the edge of the margin","Differs"))),IF(ABS(M7)/I7<0.15,"Close","Differs"))) -> Differs
A8: 7 | B8: Zaatari camp | C8: Arrival | D8: Arrived in 2014 or later | E8: 34 | F8: 234 | G8: =E8/F8 -> 0.14529915 | H8: % | I8: =Calculations!$C$30 -> 0.17 | J8: Arrival in the camp in 2014 (sum of the two half-years the report prints) | K8: REACH 2015 | L8: With care | M8: =IF(AND(ISNUMBER(G8),ISNUMBER(I8)),IF(H8="%",(G8-I8)*100,G8-I8),"") -> -2.4700855 | N8: =IF(AND(H8="%",ISNUMBER(G8),ISNUMBER(F8)),1.96*SQRT(G8*(1-G8)/F8)*100,"") -> 4.5153014 | O8: =IF(L8="No","Not the same measure",IF(H8="%",IF(ABS(M8)<10,"Close",IF(ABS(M8)<=0.9*N8,"Within the margin",IF(ABS(M8)<=1.1*N8,"At the edge of the margin","Differs"))),IF(ABS(M8)/I8<0.15,"Close","Differs"))) -> Close
A9: 8 | B9: Zaatari camp | C9: Arrival | D9: Lived outside the camp and returned | E9: 35 | F9: 257 | G9: =E9/F9 -> 0.13618677 | H9: % | I9: 0.022 | J9: Households that did not come to the camp straight from Syria, May 2014; the profile reads them as arrivals through other entry points or a neighbouring country | K9: REACH 2014 | L9: No | M9: =IF(AND(ISNUMBER(G9),ISNUMBER(I9)),IF(H9="%",(G9-I9)*100,G9-I9),"") -> 11.418677 | N9: =IF(AND(H9="%",ISNUMBER(G9),ISNUMBER(F9)),1.96*SQRT(G9*(1-G9)/F9)*100,"") -> 4.1934058 | O9: =IF(L9="No","Not the same measure",IF(H9="%",IF(ABS(M9)<10,"Close",IF(ABS(M9)<=0.9*N9,"Within the margin",IF(ABS(M9)<=1.1*N9,"At the edge of the margin","Differs"))),IF(ABS(M9)/I9<0.15,"Close","Differs"))) -> Not the same measure | P9: Not the same thing: the survey counts camp households that lived outside the camp and came back. No published figure on returns to the camp was found.
A10: 9 | B10: Zaatari camp | C10: Housing | D10: Lives in a caravan | E10: no data | F10: 16 | G10: Only 16 camp households answered the type of dwelling | H10: text | I10: 0.96 | J10: Random sample of 388 households, August 2016; the other 4% live in a caravan with a tent | K10: REACH 2016 | L10: No | M10: =IF(AND(ISNUMBER(G10),ISNUMBER(I10)),IF(H10="%",(G10-I10)*100,G10-I10),"") | N10: =IF(AND(H10="%",ISNUMBER(G10),ISNUMBER(F10)),1.96*SQRT(G10*(1-G10)/F10)*100,"") | O10: No data in the survey
A11: 10 | B11: Zaatari camp | C11: Housing | D11: Reports owning its dwelling | E11: 55 | F11: 256 | G11: =E11/F11 -> 0.21484375 | H11: % | I11: No published figure | J11: Caravans were bought and sold inside the camp although sale was not permitted | K11: IRIN 2013; Syria Direct 2025 | L11: No | M11: =IF(AND(ISNUMBER(G11),ISNUMBER(I11)),IF(H11="%",(G11-I11)*100,G11-I11),"") | N11: =IF(AND(H11="%",ISNUMBER(G11),ISNUMBER(F11)),1.96*SQRT(G11*(1-G11)/F11)*100,"") -> 5.0312454 | O11: No published figure | P11: In 2013 a caravan cost up to JD 450 inside the camp (IRIN). Most of the other camp households report a dwelling provided to them.
A12: 11 | B12: Zaatari camp | C12: Who answered | D12: A woman answered | E12: 55 | F12: 257 | G12: =E12/F12 -> 0.21400778 | H12: % | I12: 0.2 | J12: Households headed by a woman in Zaatari ("1 in 5"), April 2015 and February 2018 | K12: UNHCR Zaatari 2015 | L12: No | M12: =IF(AND(ISNUMBER(G12),ISNUMBER(I12)),IF(H12="%",(G12-I12)*100,G12-I12),"") -> 1.4007782 | N12: =IF(AND(H12="%",ISNUMBER(G12),ISNUMBER(F12)),1.96*SQRT(G12*(1-G12)/F12)*100,"") -> 5.0143358 | O12: =IF(L12="No","Not the same measure",IF(H12="%",IF(ABS(M12)<10,"Close",IF(ABS(M12)<=0.9*N12,"Within the margin",IF(ABS(M12)<=1.1*N12,"At the edge of the margin","Differs"))),IF(ABS(M12)/I12<0.15,"Close","Differs"))) -> Not the same measure | P12: The respondent is not necessarily the person who heads the household. In the camp, 41 of the 55 women who answered are married.
A13: 12 | B13: Zaatari camp | C13: Work | D13: Men in employment | E13: 58 | F13: 196 | G13: =E13/F13 -> 0.29591837 | H13: % | I13: 0.24 | J13: Men aged 15 to 64 in all official camps, 2016 | K13: JLMPS 2016 | L13: With care | M13: =IF(AND(ISNUMBER(G13),ISNUMBER(I13)),IF(H13="%",(G13-I13)*100,G13-I13),"") -> 5.5918367 | N13: =IF(AND(H13="%",ISNUMBER(G13),ISNUMBER(F13)),1.96*SQRT(G13*(1-G13)/F13)*100,"") -> 6.3903626 | O13: =IF(L13="No","Not the same measure",IF(H13="%",IF(ABS(M13)<10,"Close",IF(ABS(M13)<=0.9*N13,"Within the margin",IF(ABS(M13)<=1.1*N13,"At the edge of the margin","Differs"))),IF(ABS(M13)/I13<0.15,"Close","Differs"))) -> Close | P13: In the survey these are the men who answered (196 with an answer), not all men in the household.
A14: 13 | B14: Zaatari camp | C14: Work | D14: Work income among the household's sources | E14: 90 | F14: 248 | G14: =E14/F14 -> 0.36290323 | H14: % | I14: 0.65 | J14: Households in camps with wage income in the previous 12 months, November 2017 to January 2018 | K14: Fafo 2017-2018 | L14: With care | M14: =IF(AND(ISNUMBER(G14),ISNUMBER(I14)),IF(H14="%",(G14-I14)*100,G14-I14),"") -> -28.709677 | N14: =IF(AND(H14="%",ISNUMBER(G14),ISNUMBER(F14)),1.96*SQRT(G14*(1-G14)/F14)*100,"") -> 5.9845066 | O14: =IF(L14="No","Not the same measure",IF(H14="%",IF(ABS(M14)<10,"Close",IF(ABS(M14)<=0.9*N14,"Within the margin",IF(ABS(M14)<=1.1*N14,"At the edge of the margin","Differs"))),IF(ABS(M14)/I14<0.15,"Close","Differs"))) -> Differs | P14: A year and a half separates the two measurements. The survey records up to three income sources.
A15: 14 | B15: Zaatari camp | C15: Work | D15: Own business | E15: fewer than 10 | F15: 257 | G15: Fewer than ten households | H15: text | I15: About 3,000 informal shops and businesses in the camp | J15: Zaatari, February 2018 (PBS NewsHour reported 3,000 businesses in June 2016) | K15: UNHCR Zaatari 2018; PBS 2016 | L15: No | M15: =IF(AND(ISNUMBER(G15),ISNUMBER(I15)),IF(H15="%",(G15-I15)*100,G15-I15),"") | N15: =IF(AND(H15="%",ISNUMBER(G15),ISNUMBER(F15)),1.96*SQRT(G15*(1-G15)/F15)*100,"") | O15: =IF(L15="No","Not the same measure",IF(H15="%",IF(ABS(M15)<10,"Close",IF(ABS(M15)<=0.9*N15,"Within the margin",IF(ABS(M15)<=1.1*N15,"At the edge of the margin","Differs"))),IF(ABS(M15)/I15<0.15,"Close","Differs"))) -> Not the same measure | P15: The question captured little of the commercial activity in the camp; a count of businesses and a share of households are not the same measure.
A16: 15 | B16: Zaatari camp | C16: Assistance | D16: Names the food voucher among its sources | E16: 230 | F16: 248 | G16: =E16/F16 -> 0.92741935 | H16: % | I16: No published share | J16: WFP reports that all eligible refugees receive the monthly transfer; in camps and transit centres it reached 94,035 people with JD 20 per person in February 2016 | K16: WFP 2016; WFP 2016b | L16: No | M16: =IF(AND(ISNUMBER(G16),ISNUMBER(I16)),IF(H16="%",(G16-I16)*100,G16-I16),"") | N16: =IF(AND(H16="%",ISNUMBER(G16),ISNUMBER(F16)),1.96*SQRT(G16*(1-G16)/F16)*100,"") -> 3.2290794 | O16: No published figure | P16: The 18 camp households that do not name the voucher may have left it out: the question asks for income sources.
A17: 16 | B17: Zaatari camp | C17: Assistance | D17: Reports exactly JD 20 per person, among those naming the voucher | E17: 206 | F17: 230 | G17: =E17/F17 -> 0.89565217 | H17: % | I17: JD 20 per person per month | J17: Value of the transfer in camps and transit centres, February 2016 (WFP calls it a cash-based transfer, redeemable for food in partner shops) | K17: WFP 2016 | L17: Yes | M17: =IF(AND(ISNUMBER(G17),ISNUMBER(I17)),IF(H17="%",(G17-I17)*100,G17-I17),"") | N17: =IF(AND(H17="%",ISNUMBER(G17),ISNUMBER(F17)),1.96*SQRT(G17*(1-G17)/F17)*100,"") -> 3.9509683 | O17: Close | P17: The amount reported matches the official value in 206 of the 230 camp households that name the voucher.
A18: 17 | B18: Zaatari camp | C18: Spending | D18: Households with income below JD 28 per person | E18: 162 | F18: 248 | G18: =E18/F18 -> 0.65322581 | H18: % | I18: 0.62 | J18: Camp households (Zaatari and Azraq) at risk of abject poverty, 2015: about 62% in the text of the paper and 0.64 in its table 1; national line of JD 336 per person per year, listed under income | K18: Obi 2021 | L18: With care | M18: =IF(AND(ISNUMBER(G18),ISNUMBER(I18)),IF(H18="%",(G18-I18)*100,G18-I18),"") -> 3.3225806 | N18: =IF(AND(H18="%",ISNUMBER(G18),ISNUMBER(F18)),1.96*SQRT(G18*(1-G18)/F18)*100,"") -> 5.923594 | O18: =IF(L18="No","Not the same measure",IF(H18="%",IF(ABS(M18)<10,"Close",IF(ABS(M18)<=0.9*N18,"Within the margin",IF(ABS(M18)<=1.1*N18,"At the edge of the margin","Differs"))),IF(ABS(M18)/I18<0.15,"Close","Differs"))) -> Close | P18: With reported spending instead of income: 127 of 239 households (53.1%); counting people, 61.1% of 1,174. Reported income and spending add only what was written down.
A19: 18 | B19: Zaatari camp | C19: Debt and savings | D19: Has debts | E19: 155 | F19: 257 | G19: =E19/F19 -> 0.60311284 | H19: % | I19: No published figure for the camps | J19: CFSME 2016 publishes debt only for host communities | K19: CFSME 2016 | L19: No | M19: =IF(AND(ISNUMBER(G19),ISNUMBER(I19)),IF(H19="%",(G19-I19)*100,G19-I19),"") | N19: =IF(AND(H19="%",ISNUMBER(G19),ISNUMBER(F19)),1.96*SQRT(G19*(1-G19)/F19)*100,"") -> 5.9816682 | O19: No published figure
A20: 19 | B20: Zaatari camp | C20: Basic living conditions | D20: Has a refrigerator | E20: 114 | F20: 257 | G20: =E20/F20 -> 0.44357977 | H20: % | I20: No published figure for the camps | J20: Fafo: 89% of all households; access to durable goods is lower in the camps | K20: Fafo 2017-2018 | L20: No | M20: =IF(AND(ISNUMBER(G20),ISNUMBER(I20)),IF(H20="%",(G20-I20)*100,G20-I20),"") | N20: =IF(AND(H20="%",ISNUMBER(G20),ISNUMBER(F20)),1.96*SQRT(G20*(1-G20)/F20)*100,"") -> 6.0740286 | O20: No published figure | P20: In August 2016, 95% of Zaatari families were connected to the electricity network (REACH 2016).
A21: 20 | B21: Zaatari camp | C21: Health | D21: A member with a medical condition | E21: 60 | F21: 257 | G21: =E21/F21 -> 0.23346304 | H21: % | I21: No published figure for Zaatari | L21: No | M21: =IF(AND(ISNUMBER(G21),ISNUMBER(I21)),IF(H21="%",(G21-I21)*100,G21-I21),"") | N21: =IF(AND(H21="%",ISNUMBER(G21),ISNUMBER(F21)),1.96*SQRT(G21*(1-G21)/F21)*100,"") -> 5.1720787 | O21: No published figure | P21: Only as a share of the group.
A22: 21 | B22: Northern towns | C22: Where and who | D22: Lives in Irbid governorate (Irbid and Ramtha) | E22: 90 | F22: 134 | G22: =E22/F22 -> 0.67164179 | H22: % | I22: =Calculations!$C$16 -> 0.26364741 | J22: Registered Syrians outside the camps, end of 2016: 136,496 registered in the governorate over about 518,000 registered outside camps (79% of 655,344). The paper prints 21% of all registered Syrians, camps included | K22: Krafft et al. 2019 | L22: Yes | M22: =IF(AND(ISNUMBER(G22),ISNUMBER(I22)),IF(H22="%",(G22-I22)*100,G22-I22),"") -> 40.799438 | N22: =IF(AND(H22="%",ISNUMBER(G22),ISNUMBER(F22)),1.96*SQRT(G22*(1-G22)/F22)*100,"") -> 7.9514525 | O22: =IF(L22="No","Not the same measure",IF(H22="%",IF(ABS(M22)<10,"Close",IF(ABS(M22)<=0.9*N22,"Within the margin",IF(ABS(M22)<=1.1*N22,"At the edge of the margin","Differs"))),IF(ABS(M22)/I22<0.15,"Close","Differs"))) -> Differs | P22: In the 2015 census, 27% of all Syrians, registered or not, lived in Irbid governorate.
A23: 22 | B23: Northern towns | C23: Where and who | D23: Lives in Jerash governorate | E23: 24 | F23: 134 | G23: =E23/F23 -> 0.17910448 | H23: % | I23: =Calculations!$C$18 -> 0.018747522 | J23: Registered Syrians outside the camps, end of 2016, computed as for Irbid (the paper prints 1% of all registered Syrians) | K23: Krafft et al. 2019 | L23: Yes | M23: =IF(AND(ISNUMBER(G23),ISNUMBER(I23)),IF(H23="%",(G23-I23)*100,G23-I23),"") -> 16.035696 | N23: =IF(AND(H23="%",ISNUMBER(G23),ISNUMBER(F23)),1.96*SQRT(G23*(1-G23)/F23)*100,"") -> 6.4923337 | O23: =IF(L23="No","Not the same measure",IF(H23="%",IF(ABS(M23)<10,"Close",IF(ABS(M23)<=0.9*N23,"Within the margin",IF(ABS(M23)<=1.1*N23,"At the edge of the margin","Differs"))),IF(ABS(M23)/I23<0.15,"Close","Differs"))) -> Differs | P23: In the 2015 census, 1%.
A24: 23 | B24: Northern towns | C24: Where and who | D24: Lives in Amman governorate | E24: fewer than 10 | F24: 134 | G24: Fewer than ten households | H24: text | I24: =Calculations!$C$20 -> 0.34772732 | J24: Registered Syrians outside the camps, end of 2016, computed as for Irbid (the paper prints 28% of all registered Syrians) | K24: Krafft et al. 2019 | L24: Yes | M24: =IF(AND(ISNUMBER(G24),ISNUMBER(I24)),IF(H24="%",(G24-I24)*100,G24-I24),"") | N24: =IF(AND(H24="%",ISNUMBER(G24),ISNUMBER(F24)),1.96*SQRT(G24*(1-G24)/F24)*100,"") | O24: Differs | P24: In the 2015 census, 34%.
A25: 24 | B25: Northern towns | C25: Where and who | D25: Origin in Daraa governorate | E25: 86 | F25: 134 | G25: =E25/F25 -> 0.64179104 | H25: % | I25: 0.477 | J25: All Syrian refugees, inside and outside camps, 2017 and 2018 (table 3 of the report; 48% in its summary) | K25: Fafo 2017-2018 | L25: With care | M25: =IF(AND(ISNUMBER(G25),ISNUMBER(I25)),IF(H25="%",(G25-I25)*100,G25-I25),"") -> 16.479104 | N25: =IF(AND(H25="%",ISNUMBER(G25),ISNUMBER(F25)),1.96*SQRT(G25*(1-G25)/F25)*100,"") -> 8.1183677 | O25: =IF(L25="No","Not the same measure",IF(H25="%",IF(ABS(M25)<10,"Close",IF(ABS(M25)<=0.9*N25,"Within the margin",IF(ABS(M25)<=1.1*N25,"At the edge of the margin","Differs"))),IF(ABS(M25)/I25<0.15,"Close","Differs"))) -> Differs | P25: Within the survey: 68 of 90 households in Irbid governorate and 18 of 44 in the other places. No published origin by governorate was found.
A26: 25 | B26: Northern towns | C26: Where and who | D26: Origin in Damascus or Rif Dimashq | E26: 25 | F26: 134 | G26: =E26/F26 -> 0.18656716 | H26: % | I26: =Calculations!$C$39 -> 0.166 | J26: All Syrian refugees, 2017 and 2018 | K26: Fafo 2017-2018 | L26: With care | M26: =IF(AND(ISNUMBER(G26),ISNUMBER(I26)),IF(H26="%",(G26-I26)*100,G26-I26),"") -> 2.0567164 | N26: =IF(AND(H26="%",ISNUMBER(G26),ISNUMBER(F26)),1.96*SQRT(G26*(1-G26)/F26)*100,"") -> 6.5960225 | O26: =IF(L26="No","Not the same measure",IF(H26="%",IF(ABS(M26)<10,"Close",IF(ABS(M26)<=0.9*N26,"Within the margin",IF(ABS(M26)<=1.1*N26,"At the edge of the margin","Differs"))),IF(ABS(M26)/I26<0.15,"Close","Differs"))) -> Close
A27: 26 | B27: Northern towns | C27: Where and who | D27: Origin in Aleppo | E27: 13 | F27: 134 | G27: =E27/F27 -> 0.097014925 | H27: % | I27: 0.098 | J27: All Syrian refugees, 2017 and 2018 (table 3 of the report) | K27: Fafo 2017-2018 | L27: With care | M27: =IF(AND(ISNUMBER(G27),ISNUMBER(I27)),IF(H27="%",(G27-I27)*100,G27-I27),"") -> -0.098507463 | N27: =IF(AND(H27="%",ISNUMBER(G27),ISNUMBER(F27)),1.96*SQRT(G27*(1-G27)/F27)*100,"") -> 5.0114481 | O27: =IF(L27="No","Not the same measure",IF(H27="%",IF(ABS(M27)<10,"Close",IF(ABS(M27)<=0.9*N27,"Within the margin",IF(ABS(M27)<=1.1*N27,"At the edge of the margin","Differs"))),IF(ABS(M27)/I27<0.15,"Close","Differs"))) -> Close
A28: 27 | B28: Northern towns | C28: Where and who | D28: People per household (mean) | F28: 134 | G28: 5.1 | H28: people | I28: 5.2 | J28: Syrian refugee households, 2016 | K28: JLMPS 2016 | L28: Yes | M28: =IF(AND(ISNUMBER(G28),ISNUMBER(I28)),IF(H28="%",(G28-I28)*100,G28-I28),"") -> -0.1 | N28: =IF(AND(H28="%",ISNUMBER(G28),ISNUMBER(F28)),1.96*SQRT(G28*(1-G28)/F28)*100,"") | O28: =IF(L28="No","Not the same measure",IF(H28="%",IF(ABS(M28)<10,"Close",IF(ABS(M28)<=0.9*N28,"Within the margin",IF(ABS(M28)<=1.1*N28,"At the edge of the margin","Differs"))),IF(ABS(M28)/I28<0.15,"Close","Differs"))) -> Close | P28: Fafo gives 5.8 in Irbid and 5.3 overall, and says its mean equals that of Syrians in the 2015 census; CFSME 2016 gives 6.4 in host communities.
A29: 28 | B29: Northern towns | C29: Where and who | D29: Reports being registered as a refugee | E29: 122 | F29: 134 | G29: =E29/F29 -> 0.91044776 | H29: % | I29: 0.86 | J29: Syrians aged 15 to 59 in refugee households, 2016 | K29: JLMPS 2016; Krafft et al. 2019 | L29: Yes | M29: =IF(AND(ISNUMBER(G29),ISNUMBER(I29)),IF(H29="%",(G29-I29)*100,G29-I29),"") -> 5.0447761 | N29: =IF(AND(H29="%",ISNUMBER(G29),ISNUMBER(F29)),1.96*SQRT(G29*(1-G29)/F29)*100,"") -> 4.8346987 | O29: =IF(L29="No","Not the same measure",IF(H29="%",IF(ABS(M29)<10,"Close",IF(ABS(M29)<=0.9*N29,"Within the margin",IF(ABS(M29)<=1.1*N29,"At the edge of the margin","Differs"))),IF(ABS(M29)/I29<0.15,"Close","Differs"))) -> Close | P29: In the 2015 census, 80% of Syrians reported being registered with UNHCR or the Ministry of Interior (Krafft et al. 2019, table 1). The other 12 households in the survey reported being asylum seekers; none, unregistered.
A30: 29 | B30: Northern towns | C30: Arrival | D30: Arrived in 2012 or earlier | E30: 61 | F30: 134 | G30: =E30/F30 -> 0.45522388 | H30: % | I30: =Calculations!$C$33 -> 0.37 | J30: Syrian refugees aged 6 or more, 2016 (9% arrived in 2011 and 28% in 2012) | K30: JLMPS 2016 | L30: Yes | M30: =IF(AND(ISNUMBER(G30),ISNUMBER(I30)),IF(H30="%",(G30-I30)*100,G30-I30),"") -> 8.5223881 | N30: =IF(AND(H30="%",ISNUMBER(G30),ISNUMBER(F30)),1.96*SQRT(G30*(1-G30)/F30)*100,"") -> 8.4318956 | O30: =IF(L30="No","Not the same measure",IF(H30="%",IF(ABS(M30)<10,"Close",IF(ABS(M30)<=0.9*N30,"Within the margin",IF(ABS(M30)<=1.1*N30,"At the edge of the margin","Differs"))),IF(ABS(M30)/I30<0.15,"Close","Differs"))) -> Close | P30: Within the survey, early arrivals are concentrated in Irbid governorate: fewer than ten of the 44 households in the other places arrived in 2012 or earlier.
A31: 30 | B31: Northern towns | C31: Arrival | D31: Arrived in 2013 | E31: 53 | F31: 134 | G31: =E31/F31 -> 0.39552239 | H31: % | I31: 0.51 | J31: Syrian refugees aged 6 or more, 2016 | K31: JLMPS 2016 | L31: Yes | M31: =IF(AND(ISNUMBER(G31),ISNUMBER(I31)),IF(H31="%",(G31-I31)*100,G31-I31),"") -> -11.447761 | N31: =IF(AND(H31="%",ISNUMBER(G31),ISNUMBER(F31)),1.96*SQRT(G31*(1-G31)/F31)*100,"") -> 8.2790274 | O31: =IF(L31="No","Not the same measure",IF(H31="%",IF(ABS(M31)<10,"Close",IF(ABS(M31)<=0.9*N31,"Within the margin",IF(ABS(M31)<=1.1*N31,"At the edge of the margin","Differs"))),IF(ABS(M31)/I31<0.15,"Close","Differs"))) -> Differs
A32: 31 | B32: Northern towns | C32: Arrival | D32: Arrived in 2014 or later | E32: 20 | F32: 134 | G32: =E32/F32 -> 0.14925373 | H32: % | I32: 0.13 | J32: Syrian refugees aged 6 or more, 2016 | K32: JLMPS 2016 | L32: Yes | M32: =IF(AND(ISNUMBER(G32),ISNUMBER(I32)),IF(H32="%",(G32-I32)*100,G32-I32),"") -> 1.9253731 | N32: =IF(AND(H32="%",ISNUMBER(G32),ISNUMBER(F32)),1.96*SQRT(G32*(1-G32)/F32)*100,"") -> 6.033458 | O32: =IF(L32="No","Not the same measure",IF(H32="%",IF(ABS(M32)<10,"Close",IF(ABS(M32)<=0.9*N32,"Within the margin",IF(ABS(M32)<=1.1*N32,"At the edge of the margin","Differs"))),IF(ABS(M32)/I32<0.15,"Close","Differs"))) -> Close
A33: 32 | B33: Northern towns | C33: Arrival | D33: Passed through a camp before living outside | E33: 84 | F33: 134 | G33: =E33/F33 -> 0.62686567 | H33: % | I33: About 430,000 people passed through Zaatari; about 160,000 left informally for urban areas and about 60,000 left with a sponsor | J33: UNHCR estimate, April 2015 | K33: UNHCR Zaatari 2015 | L33: No | M33: =IF(AND(ISNUMBER(G33),ISNUMBER(I33)),IF(H33="%",(G33-I33)*100,G33-I33),"") | N33: =IF(AND(H33="%",ISNUMBER(G33),ISNUMBER(F33)),1.96*SQRT(G33*(1-G33)/F33)*100,"") -> 8.1888614 | O33: =IF(L33="No","Not the same measure",IF(H33="%",IF(ABS(M33)<10,"Close",IF(ABS(M33)<=0.9*N33,"Within the margin",IF(ABS(M33)<=1.1*N33,"At the edge of the margin","Differs"))),IF(ABS(M33)/I33<0.15,"Close","Differs"))) -> Not the same measure | P33: In the survey, 71 households lived in Zaatari and 13 in Azraq. The published figures count people who passed through one camp; the survey, households that passed through any camp.
A34: 33 | B34: Northern towns | C34: Arrival | D34: Left the camp with a sponsor (among households that passed through a camp) | E34: 42 | F34: 84 | G34: =E34/F34 -> 0.5 | H34: % | I34: =Calculations!$C$36 -> 0.27272727 | J34: People who left Zaatari: about 60,000 formally with a Jordanian sponsor and about 160,000 informally for urban areas; the share is computed from the two | K34: UNHCR Zaatari 2015 | L34: With care | M34: =IF(AND(ISNUMBER(G34),ISNUMBER(I34)),IF(H34="%",(G34-I34)*100,G34-I34),"") -> 22.727273 | N34: =IF(AND(H34="%",ISNUMBER(G34),ISNUMBER(F34)),1.96*SQRT(G34*(1-G34)/F34)*100,"") -> 10.692677 | O34: =IF(L34="No","Not the same measure",IF(H34="%",IF(ABS(M34)<10,"Close",IF(ABS(M34)<=0.9*N34,"Within the margin",IF(ABS(M34)<=1.1*N34,"At the edge of the margin","Differs"))),IF(ABS(M34)/I34<0.15,"Close","Differs"))) -> Differs | P34: The published figure is a round UNHCR estimate that counts only the two routes; in the survey the other routes have fewer than ten households, so the share among the two routes is a few points higher than the one shown. Households that left with a sponsor weigh more in the survey.
A35: 34 | B35: Northern towns | C35: Housing | D35: Rents its dwelling | E35: 116 | F35: 134 | G35: =E35/F35 -> 0.86567164 | H35: % | I35: 0.98 | J35: Syrian refugees outside camps renting in the private market, 2017 and 2018 | K35: Fafo 2017-2018 | L35: Yes | M35: =IF(AND(ISNUMBER(G35),ISNUMBER(I35)),IF(H35="%",(G35-I35)*100,G35-I35),"") -> -11.432836 | N35: =IF(AND(H35="%",ISNUMBER(G35),ISNUMBER(F35)),1.96*SQRT(G35*(1-G35)/F35)*100,"") -> 5.7738317 | O35: =IF(L35="No","Not the same measure",IF(H35="%",IF(ABS(M35)<10,"Close",IF(ABS(M35)<=0.9*N35,"Within the margin",IF(ABS(M35)<=1.1*N35,"At the edge of the margin","Differs"))),IF(ABS(M35)/I35<0.15,"Close","Differs"))) -> Differs | P35: The other 18 households in the survey report a dwelling provided to them.
A36: 35 | B36: Northern towns | C36: Housing | D36: Monthly rent of those who rent (median, JD) | F36: 105 | G36: 130 | H36: JD | I36: 135 | J36: Median monthly household spending on rent in the Fafo survey (executive summary); rents of JD 120 to 150 are reported as common, except in the group of other governorates (about JD 80) | K36: Fafo 2017-2018 | L36: With care | M36: =IF(AND(ISNUMBER(G36),ISNUMBER(I36)),IF(H36="%",(G36-I36)*100,G36-I36),"") -> -5 | N36: =IF(AND(H36="%",ISNUMBER(G36),ISNUMBER(F36)),1.96*SQRT(G36*(1-G36)/F36)*100,"") | O36: =IF(L36="No","Not the same measure",IF(H36="%",IF(ABS(M36)<10,"Close",IF(ABS(M36)<=0.9*N36,"Within the margin",IF(ABS(M36)<=1.1*N36,"At the edge of the margin","Differs"))),IF(ABS(M36)/I36<0.15,"Close","Differs"))) -> Close | P36: Survey quartiles: JD 85 and JD 165.
A37: 36 | B37: Northern towns | C37: Housing | D37: Mean rent per household, with zero for those who do not rent (JD) | F37: 123 | G37: 110.2 | H37: JD | I37: 99 | J37: Mean household spending on rent, host communities, 2016 | K37: CFSME 2016 | L37: Yes | M37: =IF(AND(ISNUMBER(G37),ISNUMBER(I37)),IF(H37="%",(G37-I37)*100,G37-I37),"") -> 11.2 | N37: =IF(AND(H37="%",ISNUMBER(G37),ISNUMBER(F37)),1.96*SQRT(G37*(1-G37)/F37)*100,"") | O37: =IF(L37="No","Not the same measure",IF(H37="%",IF(ABS(M37)<10,"Close",IF(ABS(M37)<=0.9*N37,"Within the margin",IF(ABS(M37)<=1.1*N37,"At the edge of the margin","Differs"))),IF(ABS(M37)/I37<0.15,"Close","Differs"))) -> Close | P37: Eleven households that rent did not give the amount and are left out. CFSME does not say whether households that pay no rent enter its mean.
A38: 37 | B38: Northern towns | C38: Debt and savings | D38: Has debts | E38: 92 | F38: 133 | G38: =E38/F38 -> 0.69172932 | H38: % | I38: 0.87 | J38: Households in host communities, April and May 2016 | K38: CFSME 2016 | L38: Yes | M38: =IF(AND(ISNUMBER(G38),ISNUMBER(I38)),IF(H38="%",(G38-I38)*100,G38-I38),"") -> -17.827068 | N38: =IF(AND(H38="%",ISNUMBER(G38),ISNUMBER(F38)),1.96*SQRT(G38*(1-G38)/F38)*100,"") -> 7.8480986 | O38: =IF(L38="No","Not the same measure",IF(H38="%",IF(ABS(M38)<10,"Close",IF(ABS(M38)<=0.9*N38,"Within the margin",IF(ABS(M38)<=1.1*N38,"At the edge of the margin","Differs"))),IF(ABS(M38)/I38<0.15,"Close","Differs"))) -> Differs | P38: Fafo gives two thirds of all households in 2017 and 2018, and about 80% of indebted households owe to relatives and friends in Jordan.
A39: 38 | B39: Northern towns | C39: Debt and savings | D39: Has savings | E39: fewer than 10 | F39: 133 | G39: Fewer than ten households | H39: text | I39: 0.05 | J39: Households in host communities, 2016 | K39: CFSME 2016 | L39: Yes | M39: =IF(AND(ISNUMBER(G39),ISNUMBER(I39)),IF(H39="%",(G39-I39)*100,G39-I39),"") | N39: =IF(AND(H39="%",ISNUMBER(G39),ISNUMBER(F39)),1.96*SQRT(G39*(1-G39)/F39)*100,"") | O39: Close | P39: Fafo gives 2% in 2017 and 2018.
A40: 39 | B40: Northern towns | C40: Basic living conditions | D40: Has a refrigerator | E40: nearly all | F40: 133 | G40: Nearly all | H40: text | I40: 0.89 | J40: All Syrian refugee households, 2017 and 2018 | K40: Fafo 2017-2018 | L40: With care | M40: =IF(AND(ISNUMBER(G40),ISNUMBER(I40)),IF(H40="%",(G40-I40)*100,G40-I40),"") | N40: =IF(AND(H40="%",ISNUMBER(G40),ISNUMBER(F40)),1.96*SQRT(G40*(1-G40)/F40)*100,"") | O40: Close | P40: Fewer than ten households in the towns lack one.
...

Sheet Places and districts
A1: Northern towns: where the sample lives and where Syrians live in Jordan
A2: UNHCR registration includes camp residents, and the census is described as an enumeration of all persons in Jordan: Zaatari is in Mafraq; Azraq and the Emirati camp, in Zarqa.
A4: Governorate | B4: Survey: households | C4: Survey: % | D4: UNHCR: registered at 31 Dec 2016 | E4: UNHCR: % | F4: 2015 census: all Syrians | G4: Census: %
A5: Irbid (towns of Irbid and Ramtha) | B5: 90 | C5: =B5/B$10 -> 0.67164179 | D5: 136496 | E5: =D5/D$10 -> 0.20867693 | F5: 343479 | G5: =F5/F$10 -> 0.27141462
A6: Jerash | B6: 24 | C6: =B6/B$10 -> 0.17910448 | D6: 9706 | E6: =D6/D$10 -> 0.014838664 | F6: 10868 | G6: =F6/F$10 -> 0.0085878149
A7: Zarqa | B7: 10 | C7: =B7/B$10 -> 0.074626866 | D7: 109862 | E7: =D7/D$10 -> 0.16795851 | F7: 175280 | G7: =F7/F$10 -> 0.13850499
A8: Amman, Balqa and Mafraq (fewer than ten households in each) | B8: =134-B5-B6-B7 -> 10 | C8: =B8/B$10 -> 0.074626866 | D8: 357912 | E8: =D8/D$10 -> 0.54718071 | F8: 671463 | G8: =F8/F$10 -> 0.5305852
A9: Six other governorates | B9: 0 | C9: =B9/B$10 -> 0 | D9: 40126 | E9: =D9/D$10 -> 0.061345172 | F9: 64424 | G9: =F9/F$10 -> 0.050907378
A10: Total | B10: =SUM(B5:B9) -> 134 | C10: =B10/B$10 -> 1 | D10: =SUM(D5:D9) -> 654102 | E10: =D10/D$10 -> 1 | F10: =SUM(F5:F9) -> 1265514 | G10: =F10/F$10 -> 1
A11: Within Irbid: 52 households in the city of Irbid and 38 in Ramtha. Source of the published figures: Krafft et al. 2019, tables 6 and 9.
A13: Camp: distribution of the sample across the twelve districts and households counted by REACH (January 2015)
A14: District | B14: Survey: households | C14: Survey: % | D14: REACH: households counted | E14: REACH: % | F14: Households expected in the survey | G14: Contribution to the chi-square | H14: Difference (points)
A15: 1 | B15: 27 | C15: =B15/B$27 -> 0.10843373 | D15: 1190 | E15: =D15/D$27 -> 0.085445537 | F15: =B$27*E15 -> 21.275939 | G15: =(B15-F15)^2/F15 -> 1.5399967 | H15: =(C15-E15)*100 -> 2.2988197
A16: 2 | B16: 28 | C16: =B16/B$27 -> 0.1124498 | D16: 1299 | E16: =D16/D$27 -> 0.093272061 | F16: =B$27*E16 -> 23.224743 | G16: =(B16-F16)^2/F16 -> 0.98184407 | H16: =(C16-E16)*100 -> 1.9177738
A17: 3 | B17: 11 | C17: =B17/B$27 -> 0.044176707 | D17: 897 | E17: =D17/D$27 -> 0.064407266 | F17: =B$27*E17 -> 16.037409 | G17: =(B17-F17)^2/F17 -> 1.5822688 | H17: =(C17-E17)*100 -> -2.023056
A18: 4 | B18: 18 | C18: =B18/B$27 -> 0.072289157 | D18: 848 | E18: =D18/D$27 -> 0.060888921 | F18: =B$27*E18 -> 15.161341 | G18: =(B18-F18)^2/F18 -> 0.53148222 | H18: =(C18-E18)*100 -> 1.1400236
A19: 5 | B19: 11 | C19: =B19/B$27 -> 0.044176707 | D19: 1034 | E19: =D19/D$27 -> 0.074244274 | F19: =B$27*E19 -> 18.486824 | G19: =(B19-F19)^2/F19 -> 3.0320262 | H19: =(C19-E19)*100 -> -3.0067567
A20: 6 | B20: 24 | C20: =B20/B$27 -> 0.096385542 | D20: 1269 | E20: =D20/D$27 -> 0.091117972 | F20: =B$27*E20 -> 22.688375 | G20: =(B20-F20)^2/F20 -> 0.07582561 | H20: =(C20-E20)*100 -> 0.52675699
A21: 7 | B21: 23 | C21: =B21/B$27 -> 0.092369478 | D21: 1373 | E21: =D21/D$27 -> 0.098585481 | F21: =B$27*E21 -> 24.547785 | G21: =(B21-F21)^2/F21 -> 0.097590803 | H21: =(C21-E21)*100 -> -0.62160035
A22: 8 | B22: 30 | C22: =B22/B$27 -> 0.12048193 | D22: 1506 | E22: =D22/D$27 -> 0.10813528 | F22: =B$27*E22 -> 26.925684 | G22: =(B22-F22)^2/F22 -> 0.35101873 | H22: =(C22-E22)*100 -> 1.2346651
A23: 9 | B23: 19 | C23: =B23/B$27 -> 0.076305221 | D23: 907 | E23: =D23/D$27 -> 0.065125296 | F23: =B$27*E23 -> 16.216199 | G23: =(B23-F23)^2/F23 -> 0.47788939 | H23: =(C23-E23)*100 -> 1.1179925
A24: 10 | B24: 22 | C24: =B24/B$27 -> 0.088353414 | D24: 1124 | E24: =D24/D$27 -> 0.080706541 | F24: =B$27*E24 -> 20.095929 | G24: =(B24-F24)^2/F24 -> 0.18040904 | H24: =(C24-E24)*100 -> 0.76468724
A25: 11 | B25: 20 | C25: =B25/B$27 -> 0.080321285 | D25: 1520 | E25: =D25/D$27 -> 0.10914052 | F25: =B$27*E25 -> 27.175989 | G25: =(B25-F25)^2/F25 -> 1.8948646 | H25: =(C25-E25)*100 -> -2.8819233
A26: 12 | B26: 16 | C26: =B26/B$27 -> 0.064257028 | D26: 960 | E26: =D26/D$27 -> 0.068930854 | F26: =B$27*E26 -> 17.163783 | G26: =(B26-F26)^2/F26 -> 0.078909756 | H26: =(C26-E26)*100 -> -0.46738256
A27: Total | B27: =SUM(B15:B26) -> 249 | C27: =B27/B$27 -> 1 | D27: =SUM(D15:D26) -> 13927 | E27: =D27/D$27 -> 1 | G27: =SUM(G15:G26) -> 10.824126
A28: Chi-square (sum of the contributions) | B28: =G27 -> 10.824126
A29: Degrees of freedom | B29: 11
A30: p-value | B30: =CHIDIST(B28,B29) -> 0.45811304
A31: Reading: with a p-value of 0.46 the distribution of the sample cannot be told apart from that of the households counted. Fewer than ten camp households have no district recorded.

Sheet Before the war
A1: What the two groups were like before the war (and one feature of the interview)
A2: Standardized difference: the difference between the groups divided by the average spread. Above 0.25 is regarded as a large imbalance.
A4: Trait | B4: Camp: households meeting the condition | C4: Camp: answering | D4: Camp: % | E4: Towns: households meeting the condition | F4: Towns: answering | G4: Towns: % | H4: Difference (points) | I4: Standardized difference
A5: A woman answered (feature of the interview) | B5: 55 | C5: 257 | D5: =IF(ISNUMBER(B5),B5/C5,"") -> 0.21400778 | E5: 84 | F5: 134 | G5: =IF(ISNUMBER(E5),E5/F5,"") -> 0.62686567 | H5: =(G5-D5)*100 -> 41.285789 | I5: =(G5-D5)/SQRT((D5*(1-D5)+G5*(1-G5))/2) -> 0.92074895
A6: Urban origin | B6: 54 | C6: 242 | D6: =IF(ISNUMBER(B6),B6/C6,"") -> 0.2231405 | E6: 80 | F6: 133 | G6: =IF(ISNUMBER(E6),E6/F6,"") -> 0.60150376 | H6: =(G6-D6)*100 -> 37.836326 | I6: =(G6-D6)/SQRT((D6*(1-D6)+G6*(1-G6))/2) -> 0.83257785
A7: Had savings in Syria | B7: 47 | C7: 257 | D7: =IF(ISNUMBER(B7),B7/C7,"") -> 0.18287938 | E7: 66 | F7: 133 | G7: =IF(ISNUMBER(E7),E7/F7,"") -> 0.4962406 | H7: =(G7-D7)*100 -> 31.336122 | I7: =(G7-D7)/SQRT((D7*(1-D7)+G7*(1-G7))/2) -> 0.70120523
A8: Had its own business in Syria | B8: 95 | C8: 257 | D8: =IF(ISNUMBER(B8),B8/C8,"") -> 0.36964981 | E8: 87 | F8: 133 | G8: =IF(ISNUMBER(E8),E8/F8,"") -> 0.65413534 | H8: =(G8-D8)*100 -> 28.448553 | I8: =(G8-D8)/SQRT((D8*(1-D8)+G8*(1-G8))/2) -> 0.59367679
A9: Origin in Daraa governorate | B9: 211 | C9: 246 | D9: =IF(ISNUMBER(B9),B9/C9,"") -> 0.85772358 | E9: 86 | F9: 134 | G9: =IF(ISNUMBER(E9),E9/F9,"") -> 0.64179104 | H9: =(G9-D9)*100 -> -21.593253 | I9: =(G9-D9)/SQRT((D9*(1-D9)+G9*(1-G9))/2) -> -0.51476079
A10: Respondent has upper secondary schooling or more | B10: 48 | C10: 257 | D10: =IF(ISNUMBER(B10),B10/C10,"") -> 0.18677043 | E10: 51 | F10: 134 | G10: =IF(ISNUMBER(E10),E10/F10,"") -> 0.38059701 | H10: =(G10-D10)*100 -> 19.382659 | I10: =(G10-D10)/SQRT((D10*(1-D10)+G10*(1-G10))/2) -> 0.44027048
A11: Had a car in Syria | B11: 83 | C11: 257 | D11: =IF(ISNUMBER(B11),B11/C11,"") -> 0.3229572 | E11: 66 | F11: 133 | G11: =IF(ISNUMBER(E11),E11/F11,"") -> 0.4962406 | H11: =(G11-D11)*100 -> 17.32834 | I11: =(G11-D11)/SQRT((D11*(1-D11)+G11*(1-G11))/2) -> 0.35797401
A12: Went on outings in Syria | B12: 126 | C12: 257 | D12: =IF(ISNUMBER(B12),B12/C12,"") -> 0.49027237 | E12: 80 | F12: 129 | G12: =IF(ISNUMBER(E12),E12/F12,"") -> 0.62015504 | H12: =(G12-D12)*100 -> 12.988267 | I12: =(G12-D12)/SQRT((D12*(1-D12)+G12*(1-G12))/2) -> 0.26362453
A13: Informal work in Syria | B13: 151 | C13: 257 | D13: =IF(ISNUMBER(B13),B13/C13,"") -> 0.58754864 | E13: 89 | F13: 133 | G13: =IF(ISNUMBER(E13),E13/F13,"") -> 0.66917293 | H13: =(G13-D13)*100 -> 8.1624294 | I13: =(G13-D13)/SQRT((D13*(1-D13)+G13*(1-G13))/2) -> 0.16951515
A14: Took vacations in Syria | B14: 54 | C14: 257 | D14: =IF(ISNUMBER(B14),B14/C14,"") -> 0.21011673 | E14: 20 | F14: 129 | G14: =IF(ISNUMBER(E14),E14/F14,"") -> 0.15503876 | H14: =(G14-D14)*100 -> -5.5077972 | I14: =(G14-D14)/SQRT((D14*(1-D14)+G14*(1-G14))/2) -> -0.1429345
A15: Had debts in Syria | B15: 62 | C15: 257 | D15: =IF(ISNUMBER(B15),B15/C15,"") -> 0.24124514 | E15: 34 | F15: 133 | G15: =IF(ISNUMBER(E15),E15/F15,"") -> 0.2556391 | H15: =(G15-D15)*100 -> 1.4393962 | I15: =(G15-D15)/SQRT((D15*(1-D15)+G15*(1-G15))/2) -> 0.033315532
A16: Arrived in Jordan in 2012 or earlier | B16: 104 | C16: 234 | D16: =IF(ISNUMBER(B16),B16/C16,"") -> 0.44444444 | E16: 61 | F16: 134 | G16: =IF(ISNUMBER(E16),E16/F16,"") -> 0.45522388 | H16: =(G16-D16)*100 -> 1.0779436 | I16: =(G16-D16)/SQRT((D16*(1-D16)+G16*(1-G16))/2) -> 0.021669481
A17: Owned its home in Syria | B17: 236 | C17: 257 | D17: =IF(ISNUMBER(B17),B17/C17,"") -> 0.91828794 | E17: nearly all | F17: 134 | G17: =IF(ISNUMBER(E17),E17/F17,"") | H17: not computed: one cell is masked
A18: Had a retirement pension in Syria: fewer than ten camp households; 28 of 129 in the towns (21.7%).
A19: Refrigerator, television and stove in Syria: more than nine in ten households in each group had each of them.
A21: Measures with mean and spread
A22: Trait | B22: Camp: households | C22: Camp: mean | D22: Camp: standard deviation | E22: Camp: median | F22: Towns: households | G22: Towns: mean | H22: Towns: standard deviation | I22: Towns: median | J22: Standardized difference
A23: Monthly income in Syria (thousand Syrian pounds) | B23: 253 | C23: 26 | D23: 21.3 | E23: 20 | F23: 115 | G23: 31.8 | H23: 33.3 | I23: 24 | J23: =(G23-C23)/SQRT((D23^2+H23^2)/2) -> 0.2075018
A24: Monthly income per person in Syria (thousand Syrian pounds) | B24: 253 | C24: 7.4 | D24: 11.2 | E24: 5 | F24: 115 | G24: 9.6 | H24: 21.8 | I24: 5 | J24: =(G24-C24)/SQRT((D24^2+H24^2)/2) -> 0.12694514
A25: People in the household | B25: 257 | C25: 5 | D25: 2.6 | E25: 5 | F25: 134 | G25: 5.1 | H25: 2.1 | I25: 5 | J25: =(G25-C25)/SQRT((D25^2+H25^2)/2) -> 0.042314422
A26: Age of the respondent | B26: 257 | C26: 38.6 | D26: 13.2 | E26: 37 | F26: 134 | G26: 39.8 | H26: 12.8 | I26: 36.5 | J26: =(G26-C26)/SQRT((D26^2+H26^2)/2) -> 0.09229677
A27: Income in Syria is missing for 19 households in the towns and fewer than ten in the camp; with blanks treated as missing, those households do not enter.

Sheet Findings
A1: Step 2: whom the sample represents
A3: No. | B3: Finding | C3: Where it comes from
A4: 1 | B4: The camp group is spread across the twelve districts almost exactly like the households counted by REACH in January 2015. The largest difference in a district is 3.0 points, and the chi-square does not tell the two distributions apart (10.8 with 11 degrees of freedom, p = 0.46). | C4: Places and districts sheet; REACH 2015
A5: 2 | B5: In the camp, origin matches the household-by-household count: 85.8% from Daraa in the survey and 81.7% in the count. | C5: Comparison sheet, No. 1
A6: 3 | B6: The average camp household has 5.0 people in the survey; the count gives 5.6 and Fafo 4.9 in 2017 and 2018. | C6: Comparison sheet, No. 4
A7: 4 | B7: The food voucher matches the programme record: 230 of the 248 camp households with some reported source name it and 206 report exactly JD 20 per person, the official value in the camps. | C7: Comparison sheet, No. 15 and 16; WFP 2016
A8: 5 | B8: The survey has more early arrivals. In the camp, 44% arrived in Jordan in 2012 or earlier and the count records 23% arriving in the camp in 2012 (the survey asks about arrival in Jordan and the count about arrival in the camp). In the towns the difference is smaller: 46% against 37% in JLMPS. The year is missing for 23 camp households. | C8: Comparison sheet, No. 5 and 29
A9: 6 | B9: The towns sample is from the north: 90 of the 134 households live in Irbid governorate (52 in Irbid and 38 in Ramtha) and 24 in Jerash. About 26% of registered Syrians outside the camps live in Irbid governorate and about 2% in Jerash. In Amman, where a third live, the survey has fewer than ten households. | C9: Places and districts sheet; Krafft et al. 2019
A10: 7 | B10: Origin follows geography: 64% of households in the towns come from Daraa, against 48% of all Syrian refugees (Fafo). In Irbid governorate they are 68 of 90 households; in the other places, 18 of 44. | C10: Comparison sheet, No. 24; b3_quien_respondio.py
A11: 8 | B11: In economic terms the towns group resembles the national figures: spending of JD 57 per person (CFSME 2016: JD 58), 67% of households below JD 68 per person (VAF 2015: 68% of cases), median rent of JD 130 (Fafo: JD 135), mean rent per household of JD 110 (CFSME: JD 99) and 5.1 people per household (JLMPS: 5.2; Fafo and the 2015 census: 5.3). | C11: Comparison sheet, No. 27, 35, 36, 40 and 41
A12: 9 | B12: The assistance reported by households in the towns matches the programme records: 86% name the voucher (WFP: about 83% of registered refugees in communities), 46% of them report more than JD 12 per person, the JD 20 tier of the programme (WFP: 49% of people), and 30% name UNHCR cash (about 26% of people in early 2017). The shares of people assisted are computed here from the published totals; Fafo counts households and gives 47% with UNHCR cash outside the camps in 2017 and 2018. | C12: Comparison sheet, No. 46 to 48; Calculations sheet
A13: 10 | B13: Several figures for households in the towns fall below the published ones: debt (69% against 87% in CFSME 2016; Fafo gives two thirds in 2017 and 2018), arrival in 2013 (40% against 51% in JLMPS), renting (87% against 98% in Fafo), people in households with spending below JD 68 per person (75% against 86% in the VAF), income below JD 28 per person (15% against 28% in Obi 2021), help from relatives among the income sources (fewer than ten households against 27% in Fafo) and households with a member with a medical condition (38% against 50% with a diagnosed chronic disease). The survey asks a single yes or no question on health, so its figure reads as a minimum, and it records up to three income sources. Employment of men is also lower (29% against 40%); with 49 men who answered, that difference sits at the edge of the survey margin. | C13: Comparison sheet, No. 30, 34, 37, 42, 43, 44, 50 and 51
A14: 11 | B14: In the camp the largest gap is in work: 36% of households name work income among their sources, against 65% of camp households with wage income in the previous twelve months in Fafo's survey of 2017 and 2018. A year and a half separates the two surveys and the questions differ. The camp also has more early arrivals than the count of January 2015 (see finding 5). | C14: Comparison sheet, No. 5, 6 and 13
A15: 12 | B15: Who answered: a woman in 21% of camp households and in 63% of those in the towns. The sources give about 22% of households headed by women, inside and outside the camps. In the towns, 65 of the 84 women who answered are married; the difference is consistent with interviews done by day and at home, where whoever was in answered. | C15: Comparison sheet, No. 11, 52 and 53
... A23: 20 | B23: Independent review (9 October 2026). Two separate instances of the AI assistant that prepared this review, which had produced none of the files, reviewed this workbook and its chart as a reader receives them: no table cell or formula was found wrong. They found that two readings had been typed by hand against the stated rule, that the voucher tier was defined differently from step 3, that the findings named two of the figures below the published ones where the Comparison sheet has more, and that a few notes gave a count below ten by placing two figures side by side. The edition of 13 October 2026 corrected each point and added the third reading, at the edge of the margin. | C23: How it was done sheet

Sheet Calculations
A1: Published figures that enter a calculation
A2: Rows marked Calculation are formulas over the figures above; the Comparison sheet takes them from here.
A4: Key | B4: What it is | C4: Value | D4: Source
A5: reg | B5: Syrians registered with UNHCR at 31 December 2016 | C5: 655344 | D5: Krafft et al. 2019
A6: com16 | B6: Share of registered refugees living in communities (March 2016) | C6: 0.81 | D6: WFP 2016
A7: com17 | B7: Share of registered refugees living outside the camps (March 2017) | C7: 0.79 | D7: Reach Project 2017
A8: wfp_high | B8: WFP, people in communities in the JD 20 tier (February 2016) | C8: 210880 | D8: WFP 2016
A9: wfp_low | B9: WFP, people in communities in the JD 10 tier (February 2016) | C9: 220171 | D9: WFP 2016
A10: wfp_comm | B10: WFP, people assisted in communities | C10: =$C$8+$C$9 -> 431051 | D10: Calculation
A11: wfp_cover | B11: Food voucher: people assisted among registered refugees living in communities (February 2016) | C11: =$C$10/($C$6*$C$43) -> 0.8315027 | D11: Calculation
A12: wfp_tier | B12: JD 20 tier among those assisted in communities | C12: =$C$8/$C$10 -> 0.48922285 | D12: Calculation
A13: unhcr_cash | B13: UNHCR, people with monthly cash (February 2017) | C13: 135783 | D13: Reach Project 2017
A14: unhcr_cover | B14: UNHCR cash: people assisted among registered refugees outside the camps | C14: =$C$13/($C$7*$C$5) -> 0.26227022 | D14: Calculation
A15: irbid | B15: Registered in Irbid governorate (end of 2016) | C15: 136496 | D15: Krafft et al. 2019
A16: irbid_p | B16: Irbid among registered refugees outside the camps | C16: =$C$15/($C$7*$C$5) -> 0.26364741 | D16: Calculation
A17: jerash | B17: Registered in Jerash governorate (end of 2016) | C17: 9706 | D17: Krafft et al. 2019
A18: jerash_p | B18: Jerash among registered refugees outside the camps | C18: =$C$17/($C$7*$C$5) -> 0.018747522 | D18: Calculation
A19: amman | B19: Registered in Amman governorate (end of 2016) | C19: 180026 | D19: Krafft et al. 2019
A20: amman_p | B20: Amman among registered refugees outside the camps | C20: =$C$19/($C$7*$C$5) -> 0.34772732 | D20: Calculation
A21: z_people | B21: Zaatari, people counted (January 2015) | C21: 78086 | D21: REACH 2015
A22: z_hh | B22: Zaatari, households counted (January 2015) | C22: 13927 | D22: REACH 2015
A23: z_size | B23: Zaatari, people per household | C23: =$C$21/$C$22 -> 5.6068069 | D23: Calculation
A24: z_12 | B24: Zaatari, arrived in the camp between July and December 2012 | C24: 0.23 | D24: REACH 2015
A25: z_13a | B25: Zaatari, arrived in the camp between January and June 2013 | C25: 0.46 | D25: REACH 2015
A26: z_13b | B26: Zaatari, arrived in the camp between July and December 2013 | C26: 0.14 | D26: REACH 2015
A27: z_13 | B27: Zaatari, arrived in the camp in 2013 | C27: =$C$25+$C$26 -> 0.6 | D27: Calculation
A28: z_14a | B28: Zaatari, arrived in the camp between January and June 2014 | C28: 0.15 | D28: REACH 2015
A29: z_14b | B29: Zaatari, arrived in the camp between July and December 2014 | C29: 0.02 | D29: REACH 2015
A30: z_14 | B30: Zaatari, arrived in the camp in 2014 | C30: =$C$28+$C$29 -> 0.17 | D30: Calculation
A31: j_11 | B31: JLMPS, refugees aged 6 or more who arrived in 2011 | C31: 0.09 | D31: JLMPS 2016
A32: j_12 | B32: JLMPS, arrived in 2012 | C32: 0.28 | D32: JLMPS 2016
A33: j_12a | B33: JLMPS, arrived in 2012 or earlier | C33: =$C$31+$C$32 -> 0.37 | D33: Calculation
A34: sponsor | B34: Zaatari, people who left with a sponsor (UNHCR estimate) | C34: 60000 | D34: UNHCR Zaatari 2015
A35: informal | B35: Zaatari, people who left for urban areas informally (UNHCR estimate) | C35: 160000 | D35: UNHCR Zaatari 2015
A36: sponsor_p | B36: Exits with a sponsor among the two routes | C36: =$C$34/($C$34+$C$35) -> 0.27272727 | D36: Calculation
A37: f_rif | B37: Fafo, Syrian refugees originating from Rif Dimashq (table 3) | C37: 0.085 | D37: Fafo 2017-2018
A38: f_dam | B38: Fafo, Syrian refugees originating from Damascus (table 3) | C38: 0.081 | D38: Fafo 2017-2018
A39: f_damrif | B39: Fafo, originating from Damascus or Rif Dimashq | C39: =$C$37+$C$38 -> 0.166 | D39: Calculation
A40: z_rif | B40: Zaatari, households originating from Rif Dimashq (January 2015) | C40: 0.1432 | D40: REACH 2015
A41: z_dam | B41: Zaatari, households originating from Damascus (January 2015) | C41: 0.0095 | D41: REACH 2015
...

Sheet Sources
A1: Sources of the published figures
A3: Key | B3: Citation | C3: Whom it covers | D3: When it was measured | E3: What was taken | F3: Link
A4: REACH 2015 | B4: REACH (2015). Za'atari Camp Population Count, Mafraq, Jordan: Summary of Findings, February 2015. | C4: All households in the camp, visited one by one | D4: 30 December 2014 to 18 January 2015 | E4: People and households by district, governorate of origin, period of arrival in the camp, type of shelter | F4: https://repository.impact-initiatives.org/document/impact/5949aa0e/reach_jor_report_zaatari_camp_population_count_february2015_1.pdf
A5: REACH 2016 | B5: REACH and UNHCR (2016). Zaatari camp winterization rapid assessment: shelter and NFIs. Factsheet, August 2016. | C5: Random sample of 388 Zaatari households, representative of the camp | D5: 15 to 22 August 2016 | E5: Families living in caravans and connection to the electricity network | F5: https://repository.impact-initiatives.org/document/impact/1578312c/reach_jor_factsheet_zaataricamp_winterizationassessment_shelternfis_aug2016_1.pdf
A6: UNHCR Zaatari 2015 | B6: UNHCR (2015). Zaatari Refugee Camp Factsheet, April 2015. | C6: UNHCR registration in Zaatari | D6: April 2015 | E6: One in five households headed by a woman; people who passed through the camp and how they left (formally with a Jordanian sponsor, or informally) | F6: https://m.reliefweb.int/report/956161
A7: UNHCR Zaatari 2018 | B7: UNHCR (2018). Zaatari Refugee Camp Factsheet, February 2018. | C7: UNHCR registration in Zaatari | D7: February 2018 | E7: About 3,000 informal shops and businesses; one in five households headed by a woman | F7: https://m.reliefweb.int/report/2465204
A8: JLMPS 2016 | B8: Krafft, C., Sieverding, M., Salemi, C. and Keo, C. (2018). Syrian Refugees in Jordan: Demographics, Livelihoods, Education, and Health. ERF Working Paper 1184. | C8: Jordan Labor Market Panel Survey 2016; 2015 census frame, includes unregistered Syrians, in camps and outside | D8: 2016 | E8: Year of arrival, household size, households headed by women, UNHCR registration, employment of men in camps and outside | F8: https://erf.org.eg/app/uploads/2018/04/1184_Final.pdf
A9: Krafft et al. 2019 | B9: Krafft, C., Razzaz, S., Keo, C. and Assaad, R. (2019). The Number and Characteristics of Syrians in Jordan: A Multi-Source Analysis. ERF Working Paper 1288. | C9: 2015 census (all Syrians) and UNHCR registration at 31 December 2016. Registration includes camp residents; the census is described as an enumeration of all persons in Jordan | D9: 2015 and 2016 | E9: Syrians by governorate in each source; total registered; share registered according to the census | F9: https://erf.org.eg/app/uploads/2019/02/12881.pdf
A10: Fafo 2017-2018 | B10: Tiltnes, Å., Zhang, H. and Pedersen, J. (2019). The living conditions of Syrian refugees in Jordan: Results from the 2017-2018 survey of Syrian refugees inside and outside camps. Fafo-report 2019:04. | C10: 7,632 Syrian refugee households inside and outside the camps; 2015 census frame | D10: November 2017 to January 2018 | E10: Origin, household size by place, households headed by women, debt, savings, rent, assets, income sources by place | F10: https://fafo.no/images/pub/2019/20701.pdf
A11: CFSME 2016 | B11: WFP and REACH (2016). Comprehensive Food Security Monitoring Exercise (CFSME) 2016. Final presentation and summary. | C11: 3,253 Syrian refugee households (5,252 registration cases); the figures used are for host communities | D11: April and May 2016 | E11: Debt, savings, spending per household member, rent, household size, income sources | F11: https://repository.impact-initiatives.org/document/reach/45b5fee0/reach_jor_wfp_cfsme2016_final_presentation.pdf
A12: VAF 2015 | B12: UNHCR (2015). Vulnerability Assessment Framework: Baseline Survey, May 2015. | C12: Registered Syrian refugees outside the camps | D12: 2015 | E12: People and cases below the poverty line of JD 68 per person per month | F12: https://haqqi.info/en/haqqi/research/vulnerability-assessment-framework-baseline-survey-may-2015
A13: WFP 2016 | B13: WFP (2016). WFP Jordan Situation Report #8, 15 March 2016. | C13: People reached with food assistance in February 2016, in camps and in communities | D13: February 2016 | E13: People assisted in camps and in communities, value of the transfer by tier, registered refugees and the share living in communities | F13: https://docs.wfp.org/api/documents/80497a979b1b449984087a3216fdd98f/download/
A14: Reach Project 2017 | B14: Reach Project (2017). UNHCR Jordan's Biometric Cash Assistance Program for Syrian Refugees. University of Toronto. | C14: UNHCR monthly cash programme for Syrian refugees outside the camps | D14: February and March 2017 | E14: Families and people receiving cash; share of registered refugees living outside the camps | F14: https://reachalliance.org/wp-content/uploads/2017/03/JORDAN_CaseStudy_ReachProject2017.pdf
... A21: PBS 2016 | B21: PBS NewsHour (2016). World's largest Syrian refugee camp has developed its own economy. 18 June 2016. | C21: News report from Zaatari | D21: June 2016 | E21: About 3,000 businesses in the camp | F21: https://www.pbs.org/newshour/show/worlds-largest-syrian-refugee-camp-has-developed-its-own-economy

Sheet How it was done
A1: Step 2 of the review: whom the sample represents
A2: 2016 survey, with fieldwork from June to August 2016 (recorded on 21 October 2026): 391 Syrian households in Jordan, 257 in Zaatari camp and 134 in the towns. How households were chosen (description of the fieldwork recorded on 8 October 2026; the file does not record it): in the camp, random selection within each district; in the northern towns, stratified snowball sampling, in which households are reached by referral from other households within groups set beforehand (the file does not record which groups), with interviews by day and at home. The towns group is therefore not a probability sample.
A4: What was done
A5: 1. The profile of each group was computed in the household file (b1_profile.py). The computation ran on the author's computer and only aggregates left it, verified when copied by their md5 checksum, a fingerprint of the file. Script names are in Spanish (b1_profile.py, b2_checks.py, b3_quien_respondio.py, b4_vale_exacto.py, b5_ingreso_bajo_la_linea.py).
A6: 2. For each figure, the published figure closest in time and population was sought: counts and records from the camp, representative surveys from 2014 to 2018 and records of the assistance programmes.
A7: 3. Each published figure was read at its source and read again asking for the exact sentence. The Sources sheet has the citation and the link; the Calculations sheet, the figures that enter a computation.
A8: 4. The main survey figures were counted a second time from the CSV with separate code (b2_checks.py) and matched.
A9: 5. Blind replication (9 October 2026). A separate instance of the AI assistant that prepared this review, given only written definitions and no code or results, recomputed the whole profile on the author's computer: 909 values (94 tables of the profile, the tables on who answered and the exact voucher amounts), all equal to the originals. The figures counted in people, not households, were counted again from the CSV with separate code and matched.
A10: 6. Blind reading of the published figures (9 October 2026). Separate readers were given each statement with its numbers removed and filled the blanks from the sources. Of 240 blanks, 175 came back equal to the figure used here (allowing for shares written as percentages and for rounding). Of the other 65: 38 are figures of this survey, replicated as in point 5; 14 are calculations made here from published components, which the readers confirmed; 11 come from a second source the readers had not been given (all read again afterwards); one, the share of camp residents receiving the voucher, is not printed in the source and was removed; and one, the share of Syrians registered according to the census, belongs to another paper and is now attributed to it. The reading also corrected five descriptions: the Zaatari count does list Damascus apart from Rif Dimashq; Fafo publishes a median rent; the figure on household size in the census comes from Fafo; the 2.2% of the 2014 profile measures something else; and the line used by Obi (2021) sits with income, so the comparison now uses reported income.
A12: How to read the Comparison sheet
A13: Survey: value = households meeting the condition divided by households answering. A blank is a missing value, not a zero. Amounts are in Jordanian dinars (JD) per month.
A14: Difference = survey minus published figure, in percentage points or in the unit of the row.
... A29: English edition of 23 October 2026, the fifth: it reads "fewer than ten households in Amman" where it said "almost no households", the wording of the other materials (second blind reading of the protection of households, 23 October 2026); no figure changes. The fourth edition, of 22 October 2026, withholds the survey value of No. 49 (some assistance among the sources), which with No. 46 gave a count below ten (second blind reading of the working paper, 22 October 2026). The third edition, of 21 October 2026, recorded the fieldwork months, restated the working notes as decision records and kept No. 47 on its base (the households that name the voucher) now that the lower voucher tier of step 3 also holds the households that name no voucher. The edition of 13 October 2026 carried the corrections of the independent review of 9 October 2026 (Findings sheet, last finding), defined the voucher tier (No. 47) as in step 3, applied one rule with three bands to the readings and gave the Calculations sheet keys in English.
