Workbook

Sheet Variables
A1: No. | B1: Variable | C1: Source | D1: Block | E1: What it measures | F1: Answers for | G1: Applies to | H1: Applies: camp | I1: Applies: towns | J1: Answered: camp | K1: Answered: towns | L1: % camp | M1: % towns | N1: A blank means | O1: Verdict | P1: Why
A2: 1 | B2: id | C2: Original question | D2: 01 Identification and design | E2: Household number in the file | F2: Survey design | G2: All households | H2: 257 | I2: 134 | J2: 257 | K2: 134 | L2: =IF(AND(ISNUMBER(J2),ISNUMBER(H2)),IF(H2>0,J2/H2,""),"") -> 1 | M2: =IF(AND(ISNUMBER(K2),ISNUMBER(I2)),IF(I2>0,K2/I2,""),"") -> 1 | N2: No answer | O2: Usable | P2: Unique across the 391 households; matches the original CSV.
A3: 2 | B3: no1 | C3: Original question | D3: 01 Identification and design | E3: Running number of the interview in the northern towns | F3: Survey design | G3: Households in the northern towns | H3: 0 | I3: 134 | J3: 0 | K3: 134 | L3: =IF(AND(ISNUMBER(J3),ISNUMBER(H3)),IF(H3>0,J3/H3,""),"") | M3: =IF(AND(ISNUMBER(K3),ISNUMBER(I3)),IF(I3>0,K3/I3,""),"") -> 1 | N3: Not applicable | O3: Usable | P3: Interview order in the northern towns (1 to 134). Interviews were done place by place.
A4: 3 | B4: no2 | C4: Original question | D4: 01 Identification and design | E4: Running number of the interview in the camp | F4: Survey design | G4: Camp households | H4: 257 | I4: 0 | J4: 257 | K4: 0 | L4: =IF(AND(ISNUMBER(J4),ISNUMBER(H4)),IF(H4>0,J4/H4,""),"") -> 1 | M4: =IF(AND(ISNUMBER(K4),ISNUMBER(I4)),IF(I4>0,K4/I4,""),"") | N4: Not applicable | O4: Usable | P4: Interview order in the camp (1 to 257).
A5: 4 | B5: samplegroup | C5: Original question | D5: 01 Identification and design | E5: Group: 0 Zaatari camp, 1 northern towns (outside the camp) | F5: Survey design | G5: All households | H5: 257 | I5: 134 | J5: 257 | K5: 134 | L5: =IF(AND(ISNUMBER(J5),ISNUMBER(H5)),IF(H5>0,J5/H5,""),"") -> 1 | M5: =IF(AND(ISNUMBER(K5),ISNUMBER(I5)),IF(I5>0,K5/I5,""),"") -> 1 | N5: No answer | O5: Usable | P5: 257 camp households and 134 in the towns.
A6: 5 | B6: age | C6: Original question | D6: 02 Respondent and household | E6: Age of the respondent | F6: The respondent | G6: All households | H6: 257 | I6: 134 | J6: 257 | K6: 134 | L6: =IF(AND(ISNUMBER(J6),ISNUMBER(H6)),IF(H6>0,J6/H6,""),"") -> 1 | M6: =IF(AND(ISNUMBER(K6),ISNUMBER(I6)),IF(I6>0,K6/I6,""),"") -> 1 | N6: No answer | O6: Usable with care | P6: Complete, but it is the age of the respondent, not of the household head. Fewer than ten respondents were under 18.
A7: 6 | B7: education | C7: Original question | D7: 02 Respondent and household | E7: Schooling of the respondent (five levels) | F7: The respondent | G7: All households | H7: 257 | I7: 134 | J7: 257 | K7: 134 | L7: =IF(AND(ISNUMBER(J7),ISNUMBER(H7)),IF(H7>0,J7/H7,""),"") -> 1 | M7: =IF(AND(ISNUMBER(K7),ISNUMBER(I7)),IF(I7>0,K7/I7,""),"") -> 1 | N7: No answer | O7: Usable with care | P7: Complete, but it is the schooling of the respondent, not of the household head.
A8: 7 | B8: genderf1m2 | C8: Original question | D8: 02 Respondent and household | E8: Sex of the respondent (1 woman, 2 man) | F8: The respondent | G8: All households | H8: 257 | I8: 134 | J8: 257 | K8: 134 | L8: =IF(AND(ISNUMBER(J8),ISNUMBER(H8)),IF(H8>0,J8/H8,""),"") -> 1 | M8: =IF(AND(ISNUMBER(K8),ISNUMBER(I8)),IF(I8>0,K8/I8,""),"") -> 1 | N8: No answer | O8: Usable | P8: Complete. A woman answered in 21% of camp households and in 63% of those in the towns: this conditions every opinion question.
A9: 8 | B9: civilstatuss1m2d3w4 | C9: Original question | D9: 02 Respondent and household | E9: Marital status of the respondent (single, married, divorced, widowed) | F9: The respondent | G9: All households | H9: 257 | I9: 134 | J9: 257 | K9: 134 | L9: =IF(AND(ISNUMBER(J9),ISNUMBER(H9)),IF(H9>0,J9/H9,""),"") -> 1 | M9: =IF(AND(ISNUMBER(K9),ISNUMBER(I9)),IF(I9>0,K9/I9,""),"") -> 1 | N9: No answer | O9: Usable with care | P9: Complete; it describes the respondent. In the towns, 65 of the 84 women who answered are married: the respondent does not always head the household.
A10: 9 | B10: familysize | C10: Original question | D10: 02 Respondent and household | E10: Household size | F10: The household | G10: All households | H10: 257 | I10: 134 | J10: 257 | K10: 134 | L10: =IF(AND(ISNUMBER(J10),ISNUMBER(H10)),IF(H10>0,J10/H10,""),"") -> 1 | M10: =IF(AND(ISNUMBER(K10),ISNUMBER(I10)),IF(I10>0,K10/I10,""),"") -> 1 | N10: No answer | O10: Usable | P10: Complete. There is no household roster: the number of children is unknown.
A11: 10 | B11: medicalcondition | C11: Original question | D11: 03 Health | E11: Which household member and what condition (open answer) | F11: The household | G11: Households with a member with a medical condition | H11: 60 | I11: 51 | J11: 60 | K11: 51 | L11: =IF(AND(ISNUMBER(J11),ISNUMBER(H11)),IF(H11>0,J11/H11,""),"") -> 1 | M11: =IF(AND(ISNUMBER(K11),ISNUMBER(I11)),IF(I11>0,K11/I11,""),"") -> 1 | N11: Not applicable | O11: Protected | P11: Open answer on who has which condition. Not used.
A12: 11 | B12: medicalconditionofoneofthemember | C12: Original question | D12: 03 Health | E12: A household member has a medical condition | F12: The household | G12: All households | H12: 257 | I12: 134 | J12: 257 | K12: 134 | L12: =IF(AND(ISNUMBER(J12),ISNUMBER(H12)),IF(H12>0,J12/H12,""),"") -> 1 | M12: =IF(AND(ISNUMBER(K12),ISNUMBER(I12)),IF(I12>0,K12/I12,""),"") -> 1 | N12: No answer | O12: Usable | P12: Complete and consistent with the open answer (111 households in both). Used only as a share by group.
A13: 12 | B13: status | C13: Original question | D13: 02 Respondent and household | E13: Reported status with UNHCR: registered refugee or asylum seeker | F13: The household | G13: All households | H13: 257 | I13: 134 | J13: 257 | K13: 134 | L13: =IF(AND(ISNUMBER(J13),ISNUMBER(H13)),IF(H13>0,J13/H13,""),"") -> 1 | M13: =IF(AND(ISNUMBER(K13),ISNUMBER(I13)),IF(I13>0,K13/I13,""),"") -> 1 | N13: No answer | O13: Not usable | P13: Not enough variation: 12 households in the towns and fewer than ten in the camp reported being asylum seekers.
... A36: 35 | B36: monthsnontreatment | C36: Original question | D36: 05 Arrival and trajectory | E36: Months in the camp before leaving | F36: The household | G36: Households in the towns that passed through a camp | H36: 0 | I36: 84 | J36: 0 | K36: 28 | L36: =IF(AND(ISNUMBER(J36),ISNUMBER(H36)),IF(H36>0,J36/H36,""),"") | M36: =IF(AND(ISNUMBER(K36),ISNUMBER(I36)),IF(I36>0,K36/I36,""),"") -> 0.33333333 | N36: The duration may be in another unit (days, months or years) | O36: Usable with care | P36: Time in the camp before leaving: nearly all of the 84 households have it, most in days, 28 in months and fewer than ten in years.
A37: 36 | B37: yearsnontreatment | C37: Original question | D37: 05 Arrival and trajectory | E37: Years in the camp before leaving | F37: The household | G37: Households in the towns that passed through a camp | H37: 0 | I37: 84 | J37: 0 | K37: fewer than 10 | L37: =IF(AND(ISNUMBER(J37),ISNUMBER(H37)),IF(H37>0,J37/H37,""),"") | M37: =IF(AND(ISNUMBER(K37),ISNUMBER(I37)),IF(I37>0,K37/I37,""),"") | N37: The duration may be in another unit (days, months or years) | O37: Usable with care | P37: Time in the camp before leaving: nearly all of the 84 households have it, most in days, 28 in months and fewer than ten in years.
A38: 37 | B38: daysundertreatment | C38: Original question | D38: 05 Arrival and trajectory | E38: Days living outside the camp | F38: The household | G38: Households in the northern towns | H38: 0 | I38: 134 | J38: 0 | K38: fewer than 10 | L38: =IF(AND(ISNUMBER(J38),ISNUMBER(H38)),IF(H38>0,J38/H38,""),"") | M38: =IF(AND(ISNUMBER(K38),ISNUMBER(I38)),IF(I38>0,K38/I38,""),"") | N38: The duration may be in another unit (days, months or years) | O38: Not usable | P38: Fewer than ten answers.
A39: 38 | B39: monthsundertreatment | C39: Original question | D39: 05 Arrival and trajectory | E39: Months living outside the camp | F39: The household | G39: Households in the northern towns | H39: 0 | I39: 134 | J39: 0 | K39: fewer than 10 | L39: =IF(AND(ISNUMBER(J39),ISNUMBER(H39)),IF(H39>0,J39/H39,""),"") | M39: =IF(AND(ISNUMBER(K39),ISNUMBER(I39)),IF(I39>0,K39/I39,""),"") | N39: The duration may be in another unit (days, months or years) | O39: Not usable | P39: Fewer than ten answers.
A40: 39 | B40: yearsundertreatment | C40: Original question | D40: 05 Arrival and trajectory | E40: Years living outside the camp | F40: The household | G40: Households in the northern towns | H40: 0 | I40: 134 | J40: 0 | K40: 78 | L40: =IF(AND(ISNUMBER(J40),ISNUMBER(H40)),IF(H40>0,J40/H40,""),"") | M40: =IF(AND(ISNUMBER(K40),ISNUMBER(I40)),IF(I40>0,K40/I40,""),"") -> 0.58208955 | N40: The duration may be in another unit (days, months or years) | O40: Usable with care | P40: 78 of 134 households in the towns; for the rest only the year of arrival remains.
A41: 40 | B41: leavepermityes1no2 | C41: Original question | D41: 05 Arrival and trajectory | E41: Holds a leave permit from the camp (1 yes, 2 no) | F41: The household | G41: All households | H41: 257 | I41: 134 | J41: 248 | K41: 122 | L41: =IF(AND(ISNUMBER(J41),ISNUMBER(H41)),IF(H41>0,J41/H41,""),"") -> 0.96498054 | M41: =IF(AND(ISNUMBER(K41),ISNUMBER(I41)),IF(I41>0,K41/I41,""),"") -> 0.91044776 | N41: No answer | O41: Not usable | P41: No variation: no yes in the camp and fewer than ten in the towns.
A42: 41 | B42: housesyria | C42: Original question | D42: 07 Housing | E42: Number of dwellings of the household in Syria | F42: The household | G42: All households | H42: 257 | I42: 134 | J42: 257 | K42: 134 | L42: =IF(AND(ISNUMBER(J42),ISNUMBER(H42)),IF(H42>0,J42/H42,""),"") -> 1 | M42: =IF(AND(ISNUMBER(K42),ISNUMBER(I42)),IF(I42>0,K42/I42,""),"") -> 1 | N42: No answer | O42: Usable with care | P42: It is a count of dwellings in Syria, not a type: nearly all households had one.
A43: 42 | B43: hsownershipo1i2r3d4 | C43: Original question | D43: 07 Housing | E43: Housing tenure in Syria (O, I, R, D) | F43: The household | G43: All households | H43: 257 | I43: 134 | J43: 257 | K43: 134 | L43: =IF(AND(ISNUMBER(J43),ISNUMBER(H43)),IF(H43>0,J43/H43,""),"") -> 1 | M43: =IF(AND(ISNUMBER(K43),ISNUMBER(I43)),IF(I43>0,K43/I43,""),"") -> 1 | N43: No answer | O43: Usable | P43: Complete. 236 camp households owned their home; in the towns, nearly all.
A44: 43 | B44: hstype | C44: Original question | D44: 07 Housing | E44: Type of dwelling in Syria | F44: The household | G44: All households | H44: 257 | I44: 134 | J44: 257 | K44: 134 | L44: =IF(AND(ISNUMBER(J44),ISNUMBER(H44)),IF(H44>0,J44/H44,""),"") -> 1 | M44: =IF(AND(ISNUMBER(K44),ISNUMBER(I44)),IF(I44>0,K44/I44,""),"") -> 1 | N44: No answer | O44: Usable | P44: Complete (house or apartment).
A45: 44 | B45: housejordan | C45: Original question | D45: 07 Housing | E45: Number of dwellings of the household in Jordan (shelters or caravans in the camp) | F45: The household | G45: All households | H45: 257 | I45: 134 | J45: 257 | K45: 134 | L45: =IF(AND(ISNUMBER(J45),ISNUMBER(H45)),IF(H45>0,J45/H45,""),"") -> 1 | M45: =IF(AND(ISNUMBER(K45),ISNUMBER(I45)),IF(I45>0,K45/I45,""),"") -> 1 | N45: No answer | O45: Usable with care | P45: In the camp it counts shelters or caravans (one to five); in the towns it is always one. Usable only within the camp.
A46: 45 | B46: hjownershipo1i2r3d4 | C46: Original question | D46: 07 Housing | E46: Housing tenure in Jordan (O, I, R, D) | F46: The household | G46: All households | H46: 257 | I46: 134 | J46: 256 | K46: 134 | L46: =IF(AND(ISNUMBER(J46),ISNUMBER(H46)),IF(H46>0,J46/H46,""),"") -> 0.99610895 | M46: =IF(AND(ISNUMBER(K46),ISNUMBER(I46)),IF(I46>0,K46/I46,""),"") -> 1 | N46: No answer | O46: Usable | P46: Nearly complete. In the towns, 116 of 134 households rent; in the camp, 55 households report owning their dwelling and most of the rest a dwelling provided to them.
A47: 46 | B47: hjtype | C47: Original question | D47: 07 Housing | E47: Type of dwelling in Jordan | F47: The household | G47: All households | H47: 257 | I47: 134 | J47: 16 | K47: 132 | L47: =IF(AND(ISNUMBER(J47),ISNUMBER(H47)),IF(H47>0,J47/H47,""),"") -> 0.062256809 | M47: =IF(AND(ISNUMBER(K47),ISNUMBER(I47)),IF(I47>0,K47/I47,""),"") -> 0.98507463 | N47: No answer | O47: Usable with care | P47: Nearly complete in the towns, where nearly all live in an apartment; in the camp there are only 16 answers.
A48: 47 | B48: tvs | C48: Original question | D48: 08 Durable goods | E48: Televisions in Syria | F48: The household | G48: All households | H48: 257 | I48: 134 | J48: 257 | K48: 133 | L48: =IF(AND(ISNUMBER(J48),ISNUMBER(H48)),IF(H48>0,J48/H48,""),"") -> 1 | M48: =IF(AND(ISNUMBER(K48),ISNUMBER(I48)),IF(I48>0,K48/I48,""),"") -> 0.99253731 | N48: No answer | O48: Usable | P48: Nearly complete (257 and 133). Recalled, but concrete.
A49: 48 | B49: tvj | C49: Original question | D49: 08 Durable goods | E49: Televisions in Jordan | F49: The household | G49: All households | H49: 257 | I49: 134 | J49: 257 | K49: 133 | L49: =IF(AND(ISNUMBER(J49),ISNUMBER(H49)),IF(H49>0,J49/H49,""),"") -> 1 | M49: =IF(AND(ISNUMBER(K49),ISNUMBER(I49)),IF(I49>0,K49/I49,""),"") -> 0.99253731 | N49: No answer | O49: Usable | P49: Nearly complete (257 and 133).
A50: 49 | B50: refrigeratorss | C50: Original question | D50: 08 Durable goods | E50: Refrigerators in Syria | F50: The household | G50: All households | H50: 257 | I50: 134 | J50: 257 | K50: 133 | L50: =IF(AND(ISNUMBER(J50),ISNUMBER(H50)),IF(H50>0,J50/H50,""),"") -> 1 | M50: =IF(AND(ISNUMBER(K50),ISNUMBER(I50)),IF(I50>0,K50/I50,""),"") -> 0.99253731 | N50: No answer | O50: Usable | P50: Nearly complete (257 and 133). Recalled, but concrete.
A51: 50 | B51: refrigeratorsj | C51: Original question | D51: 08 Durable goods | E51: Refrigerators in Jordan | F51: The household | G51: All households | H51: 257 | I51: 134 | J51: 257 | K51: 133 | L51: =IF(AND(ISNUMBER(J51),ISNUMBER(H51)),IF(H51>0,J51/H51,""),"") -> 1 | M51: =IF(AND(ISNUMBER(K51),ISNUMBER(I51)),IF(I51>0,K51/I51,""),"") -> 0.99253731 | N51: No answer | O51: Usable | P51: Nearly complete (257 and 133).
... A73: 72 | B73: occupations | C73: Original question | D73: 12 Work | E73: Occupation of the respondent in Syria | F73: The respondent | G73: All households | H73: 257 | I73: 134 | J73: 244 | K73: 126 | L73: =IF(AND(ISNUMBER(J73),ISNUMBER(H73)),IF(H73>0,J73/H73,""),"") -> 0.94941634 | M73: =IF(AND(ISNUMBER(K73),ISNUMBER(I73)),IF(I73>0,K73/I73,""),"") -> 0.94029851 | N73: No answer | O73: Usable with care | P73: Occupation of the respondent in Syria, in 48 distinct texts.
A74: 73 | B74: occupationsfather | C74: Original question | D74: 12 Work | E74: Occupation of the father in Syria, when another person answered | F74: The father or the mother | G74: Only where applicable | J74: 27 | K74: 22 | L74: =IF(AND(ISNUMBER(J74),ISNUMBER(H74)),IF(H74>0,J74/H74,""),"") | M74: =IF(AND(ISNUMBER(K74),ISNUMBER(I74)),IF(I74>0,K74/I74,""),"") | N74: Cannot be known | O74: Not usable | P74: 49 answers: filled in only when another household member answered.
A75: 74 | B75: occupationj | C75: Original question | D75: 12 Work | E75: Occupation of the respondent in Jordan | F75: The respondent | G75: All households | H75: 257 | I75: 134 | J75: 249 | K75: 126 | L75: =IF(AND(ISNUMBER(J75),ISNUMBER(H75)),IF(H75>0,J75/H75,""),"") -> 0.9688716 | M75: =IF(AND(ISNUMBER(K75),ISNUMBER(I75)),IF(I75>0,K75/I75,""),"") -> 0.94029851 | N75: No answer | O75: Usable with care | P75: Occupation of the respondent in Jordan, in 33 texts; includes housewife and no work.
A76: 75 | B76: occupationjfather | C76: Original question | D76: 12 Work | E76: Occupation of the father in Jordan, when another person answered | F76: The father or the mother | G76: Only where applicable | J76: 23 | K76: 22 | L76: =IF(AND(ISNUMBER(J76),ISNUMBER(H76)),IF(H76>0,J76/H76,""),"") | M76: =IF(AND(ISNUMBER(K76),ISNUMBER(I76)),IF(I76>0,K76/I76,""),"") | N76: Cannot be known | O76: Not usable | P76: 45 answers; it enters only combined in JobHHHJordan.
A77: 76 | B77: psourceins | C77: Original question | D77: 13 Income by source | E77: Main source of income in Syria | F77: The household | G77: All households | H77: 257 | I77: 134 | J77: 254 | K77: 131 | L77: =IF(AND(ISNUMBER(J77),ISNUMBER(H77)),IF(H77>0,J77/H77,""),"") -> 0.98832685 | M77: =IF(AND(ISNUMBER(K77),ISNUMBER(I77)),IF(I77>0,K77/I77,""),"") -> 0.97761194 | N77: No answer | O77: Usable | P77: 254 and 131 answers. The father's work is the main source in 320 households.
A78: 77 | B78: psourceinsamount | C78: Original question | D78: 13 Income by source | E78: Monthly amount of the main source in Syria | F78: The household | G78: All households | H78: 257 | I78: 134 | J78: 253 | K78: 115 | L78: =IF(AND(ISNUMBER(J78),ISNUMBER(H78)),IF(H78>0,J78/H78,""),"") -> 0.9844358 | M78: =IF(AND(ISNUMBER(K78),ISNUMBER(I78)),IF(I78>0,K78/I78,""),"") -> 0.85820896 | N78: No answer | O78: Usable with care | P78: Recalled amount in Syrian pounds. In the towns, 115 of 134 households gave it; 16 name the source without the amount.
A79: 78 | B79: ssourceins | C79: Original question | D79: 13 Income by source | E79: Second source of income in Syria | F79: The household | G79: Only where applicable | J79: fewer than 10 | K79: 16 | L79: =IF(AND(ISNUMBER(J79),ISNUMBER(H79)),IF(H79>0,J79/H79,""),"") | M79: =IF(AND(ISNUMBER(K79),ISNUMBER(I79)),IF(I79>0,K79/I79,""),"") | N79: Not applicable | O79: Not usable | P79: Fewer than 30 households report a second source in Syria.
A80: 79 | B80: ssourceinsamount | C80: Original question | D80: 13 Income by source | E80: Monthly amount of the second source in Syria | F80: The household | G80: Only where applicable | J80: fewer than 10 | K80: 15 | L80: =IF(AND(ISNUMBER(J80),ISNUMBER(H80)),IF(H80>0,J80/H80,""),"") | M80: =IF(AND(ISNUMBER(K80),ISNUMBER(I80)),IF(I80>0,K80/I80,""),"") | N80: Not applicable | O80: Not usable | P80: Fewer than 30 households report a second source in Syria.
A81: 80 | B81: tsourceins | C81: Original question | D81: 13 Income by source | E81: Third source of income in Syria | F81: The household | G81: Only where applicable | J81: 0 | K81: fewer than 10 | L81: =IF(AND(ISNUMBER(J81),ISNUMBER(H81)),IF(H81>0,J81/H81,""),"") | M81: =IF(AND(ISNUMBER(K81),ISNUMBER(I81)),IF(I81>0,K81/I81,""),"") | N81: Not applicable | O81: Not usable | P81: Fewer than ten households.
A82: 81 | B82: tsourceinsamount | C82: Original question | D82: 13 Income by source | E82: Monthly amount of the third source in Syria | F82: The household | G82: Only where applicable | J82: 0 | K82: fewer than 10 | L82: =IF(AND(ISNUMBER(J82),ISNUMBER(H82)),IF(H82>0,J82/H82,""),"") | M82: =IF(AND(ISNUMBER(K82),ISNUMBER(I82)),IF(I82>0,K82/I82,""),"") | N82: Not applicable | O82: Not usable | P82: Fewer than ten households.
A83: 82 | B83: psourceinj | C83: Original question | D83: 13 Income by source | E83: Main source of income in Jordan | F83: The household | G83: All households | H83: 257 | I83: 134 | J83: 248 | K83: 132 | L83: =IF(AND(ISNUMBER(J83),ISNUMBER(H83)),IF(H83>0,J83/H83,""),"") -> 0.96498054 | M83: =IF(AND(ISNUMBER(K83),ISNUMBER(I83)),IF(I83>0,K83/I83,""),"") -> 0.98507463 | N83: No answer | O83: Usable | P83: 248 and 132 answers. It separates WFP vouchers, UNHCR cash, work and help from relatives.
...

Sheet Summary
A1: Verdicts by block
A2: Each number is computed from the Variables sheet; if a verdict is changed there, this sheet updates.
A4: Block | B4: Variables | C4: Usable | D4: Usable with care | E4: Not usable | F4: Protected
A5: 01 Identification and design | B5: =COUNTIF(Variables!$D:$D,$A5) -> 7 | C5: =COUNTIFS(Variables!$D:$D,$A5,Variables!$O:$O,C$4) -> 6 | D5: =COUNTIFS(Variables!$D:$D,$A5,Variables!$O:$O,D$4) -> 0 | E5: =COUNTIFS(Variables!$D:$D,$A5,Variables!$O:$O,E$4) -> 1 | F5: =COUNTIFS(Variables!$D:$D,$A5,Variables!$O:$O,F$4) -> 0
A6: 02 Respondent and household | B6: =COUNTIF(Variables!$D:$D,$A6) -> 6 | C6: =COUNTIFS(Variables!$D:$D,$A6,Variables!$O:$O,C$4) -> 2 | D6: =COUNTIFS(Variables!$D:$D,$A6,Variables!$O:$O,D$4) -> 3 | E6: =COUNTIFS(Variables!$D:$D,$A6,Variables!$O:$O,E$4) -> 1 | F6: =COUNTIFS(Variables!$D:$D,$A6,Variables!$O:$O,F$4) -> 0
A7: 03 Health | B7: =COUNTIF(Variables!$D:$D,$A7) -> 2 | C7: =COUNTIFS(Variables!$D:$D,$A7,Variables!$O:$O,C$4) -> 1 | D7: =COUNTIFS(Variables!$D:$D,$A7,Variables!$O:$O,D$4) -> 0 | E7: =COUNTIFS(Variables!$D:$D,$A7,Variables!$O:$O,E$4) -> 0 | F7: =COUNTIFS(Variables!$D:$D,$A7,Variables!$O:$O,F$4) -> 1
A8: 04 Origin | B8: =COUNTIF(Variables!$D:$D,$A8) -> 4 | C8: =COUNTIFS(Variables!$D:$D,$A8,Variables!$O:$O,C$4) -> 2 | D8: =COUNTIFS(Variables!$D:$D,$A8,Variables!$O:$O,D$4) -> 1 | E8: =COUNTIFS(Variables!$D:$D,$A8,Variables!$O:$O,E$4) -> 1 | F8: =COUNTIFS(Variables!$D:$D,$A8,Variables!$O:$O,F$4) -> 0
A9: 05 Arrival and trajectory | B9: =COUNTIF(Variables!$D:$D,$A9) -> 20 | C9: =COUNTIFS(Variables!$D:$D,$A9,Variables!$O:$O,C$4) -> 5 | D9: =COUNTIFS(Variables!$D:$D,$A9,Variables!$O:$O,D$4) -> 10 | E9: =COUNTIFS(Variables!$D:$D,$A9,Variables!$O:$O,E$4) -> 5 | F9: =COUNTIFS(Variables!$D:$D,$A9,Variables!$O:$O,F$4) -> 0
A10: 06 Family events | B10: =COUNTIF(Variables!$D:$D,$A10) -> 2 | C10: =COUNTIFS(Variables!$D:$D,$A10,Variables!$O:$O,C$4) -> 0 | D10: =COUNTIFS(Variables!$D:$D,$A10,Variables!$O:$O,D$4) -> 0 | E10: =COUNTIFS(Variables!$D:$D,$A10,Variables!$O:$O,E$4) -> 0 | F10: =COUNTIFS(Variables!$D:$D,$A10,Variables!$O:$O,F$4) -> 2
A11: 07 Housing | B11: =COUNTIF(Variables!$D:$D,$A11) -> 6 | C11: =COUNTIFS(Variables!$D:$D,$A11,Variables!$O:$O,C$4) -> 3 | D11: =COUNTIFS(Variables!$D:$D,$A11,Variables!$O:$O,D$4) -> 3 | E11: =COUNTIFS(Variables!$D:$D,$A11,Variables!$O:$O,E$4) -> 0 | F11: =COUNTIFS(Variables!$D:$D,$A11,Variables!$O:$O,F$4) -> 0
A12: 08 Durable goods | B12: =COUNTIF(Variables!$D:$D,$A12) -> 8 | C12: =COUNTIFS(Variables!$D:$D,$A12,Variables!$O:$O,C$4) -> 8 | D12: =COUNTIFS(Variables!$D:$D,$A12,Variables!$O:$O,D$4) -> 0 | E12: =COUNTIFS(Variables!$D:$D,$A12,Variables!$O:$O,E$4) -> 0 | F12: =COUNTIFS(Variables!$D:$D,$A12,Variables!$O:$O,F$4) -> 0
A13: 09 Leisure | B13: =COUNTIF(Variables!$D:$D,$A13) -> 4 | C13: =COUNTIFS(Variables!$D:$D,$A13,Variables!$O:$O,C$4) -> 4 | D13: =COUNTIFS(Variables!$D:$D,$A13,Variables!$O:$O,D$4) -> 0 | E13: =COUNTIFS(Variables!$D:$D,$A13,Variables!$O:$O,E$4) -> 0 | F13: =COUNTIFS(Variables!$D:$D,$A13,Variables!$O:$O,F$4) -> 0
A14: 10 Savings, debt and credit | B14: =COUNTIF(Variables!$D:$D,$A14) -> 8 | C14: =COUNTIFS(Variables!$D:$D,$A14,Variables!$O:$O,C$4) -> 8 | D14: =COUNTIFS(Variables!$D:$D,$A14,Variables!$O:$O,D$4) -> 0 | E14: =COUNTIFS(Variables!$D:$D,$A14,Variables!$O:$O,E$4) -> 0 | F14: =COUNTIFS(Variables!$D:$D,$A14,Variables!$O:$O,F$4) -> 0
A15: 11 Average day | B15: =COUNTIF(Variables!$D:$D,$A15) -> 1 | C15: =COUNTIFS(Variables!$D:$D,$A15,Variables!$O:$O,C$4) -> 0 | D15: =COUNTIFS(Variables!$D:$D,$A15,Variables!$O:$O,D$4) -> 1 | E15: =COUNTIFS(Variables!$D:$D,$A15,Variables!$O:$O,E$4) -> 0 | F15: =COUNTIFS(Variables!$D:$D,$A15,Variables!$O:$O,F$4) -> 0
A16: 12 Work | B16: =COUNTIF(Variables!$D:$D,$A16) -> 20 | C16: =COUNTIFS(Variables!$D:$D,$A16,Variables!$O:$O,C$4) -> 2 | D16: =COUNTIFS(Variables!$D:$D,$A16,Variables!$O:$O,D$4) -> 15 | E16: =COUNTIFS(Variables!$D:$D,$A16,Variables!$O:$O,E$4) -> 3 | F16: =COUNTIFS(Variables!$D:$D,$A16,Variables!$O:$O,F$4) -> 0
... A32: 36 Derived: security, self-rated integration and shocks | B32: =COUNTIF(Variables!$D:$D,$A32) -> 12 | C32: =COUNTIFS(Variables!$D:$D,$A32,Variables!$O:$O,C$4) -> 0 | D32: =COUNTIFS(Variables!$D:$D,$A32,Variables!$O:$O,D$4) -> 10 | E32: =COUNTIFS(Variables!$D:$D,$A32,Variables!$O:$O,E$4) -> 2 | F32: =COUNTIFS(Variables!$D:$D,$A32,Variables!$O:$O,F$4) -> 0
A33: Total | B33: =SUM(B5:B32) -> 275 | C33: =SUM(C5:C32) -> 50 | D33: =SUM(D5:D32) -> 145 | E33: =SUM(E5:E32) -> 77 | F33: =SUM(F5:F32) -> 3
A35: By source
A36: Source | B36: Variables | C36: Usable | D36: Usable with care | E36: Not usable | F36: Protected
A37: Original question | B37: =COUNTIF(Variables!$C:$C,$A37) -> 153 | C37: =COUNTIFS(Variables!$C:$C,$A37,Variables!$O:$O,C$36) -> 47 | D37: =COUNTIFS(Variables!$C:$C,$A37,Variables!$O:$O,D$36) -> 73 | E37: =COUNTIFS(Variables!$C:$C,$A37,Variables!$O:$O,E$36) -> 30 | F37: =COUNTIFS(Variables!$C:$C,$A37,Variables!$O:$O,F$36) -> 3
A38: Derived | B38: =COUNTIF(Variables!$C:$C,$A38) -> 122 | C38: =COUNTIFS(Variables!$C:$C,$A38,Variables!$O:$O,C$36) -> 3 | D38: =COUNTIFS(Variables!$C:$C,$A38,Variables!$O:$O,D$36) -> 72 | E38: =COUNTIFS(Variables!$C:$C,$A38,Variables!$O:$O,E$36) -> 47 | F38: =COUNTIFS(Variables!$C:$C,$A38,Variables!$O:$O,F$36) -> 0
A40: Usable: answered by nearly all households, measures a concrete fact and is consistent with the rest of the file.
A41: Usable with care: it can be used, with the caution stated in the "Why" column.
A42: Not usable: very few answers, no variation, blanks that cannot be interpreted, or a derived variable with an error.
A43: Protected: not used, to protect households.

Sheet Findings
A1: No. | B1: Topic | C1: Finding | D1: Where it comes from
A2: 1 | B2: Fieldwork | C2: Fieldwork ran from June to August 2016 (as recorded on 21 October 2026). The two documents from 2016 and 2017 in the folder say the survey was administered in June and July 2016, and the published essay says May to July. | D2: Record of 21 October 2026; Felipe Rodriguez-Preliminary Results.docx, section 2.1
A3: 2 | B3: Fieldwork | C3: The file has no interview date. In the raw sheet named Hoja3 only 16 records carry a date, all on the same day of August 2016. Ramadan ran from 6 June to 5 July 2016. | D3: Data.xlsx, sheet Hoja3 (counts only)
A4: 3 | B4: Fieldwork | C4: In the northern towns, interviews were done place by place: across the 134 interviews there are 14 consecutive runs of the same place; a random order would give between 89 and 108 (200,000 random reorderings). Irbid 52, Ramtha 38, Jerash 24, Zarqa 10 and three places with fewer than ten households. | D4: a1_values.py, section 9
A5: 4 | B5: Fieldwork | C5: In the camp, the interview order moves through the districts with less clustering: 168 runs; a random order would give between 227 and 244. | D5: a1_values.py, section 9
A6: 5 | B6: Who answered | C6: A woman answered in 21% of camp households and in 63% of those in the towns. In the towns, 65 of the 84 women who answered are married: the respondent does not always head the household. The thesis treated age and schooling as those of the household head. | D6: a1_values.py, section 2
A7: 6 | B7: Questionnaire | C7: The original questionnaire is not in the folder. The documents from 2016 and 2017 say that shocks and responses were asked for the whole period since arrival in Jordan. | D7: Felipe Rodriguez-Preliminary Results.docx, section 2.1
A8: 7 | B8: Responses to the fall in income | C8: The eleven responses were asked of all households: nearly all of the 49 whose income did not fall answered all of them. | D8: a3_logic.py, section 3
A9: 8 | B9: Security | C9: Security was recorded as a number in the camp and as a word in the towns. The 1 to 5 scale of the thesis joins the two formats. | D9: a2_derived.py, section 8
A10: 9 | B10: Opinion scales | C10: Answers cluster at the ends. In self-rated integration (personal), 28% of camp households answered 10 and 29% of those in the towns answered 1. In optimism, 27% of those in the towns answered 1. | D10: a1_values.py, section 6
A11: 10 | B11: Work | C11: Employment is that of the respondent: among men, 30% in the camp and 29% in the towns. "Some member works" comes from another question (who works): 39% and 64%. The unemployment variable of the thesis does not follow reported employment: in 54 households the respondent reports no employment and the variable shows an occupation, and the opposite case has fewer than ten households in each group. | D11: a2_derived.py, section 9; a3_logic.py, section 8
A12: 11 | B12: Income and spending | C12: Reported total spending exceeds reported income in 45% of camp households and 50% of those in the towns (231 and 119 households with both figures). Among camp households that report assistance only, in 59%. | D12: additional check on totalexj and the three income sources
A13: 12 | B13: Spending | C13: No spending item has a written zero: a blank may be zero or no answer. | D13: a3_logic.py, section 7
... A24: 23 | B24: Thesis | C24: One of the specifications in the do-file used the medical condition indicator as a matching variable (nearest-neighbour matching, the Stata command teffects nnmatch), together with schooling, savings, origin, sex of the respondent, year of arrival and agriculture. | D24: do file creating variable.do, teffects nnmatch with medicalconditionofoneofthemember

Sheet How it was done
A1: Topic | B1: Detail
A2: What was reviewed | B2: The 275 variables of data set.dta (391 households: 257 in Zaatari camp and 134 in the northern towns), the original CSV (Coded Data.csv), the two documents from 2016 and 2017, the two do-files (the Stata scripts that built the variables and ran the estimates of the thesis) and the structure of the raw sheets (Data.xlsx and Coded data.xlsx).
A3: What was not done | B3: Nothing was estimated. This table describes how each variable was measured; it does not compare outcomes between groups.
A4: Protection of households | B4: Everything was computed on the author's computer. Only counts by variable left it. No count below ten households appears in this table: it shows as "fewer than 10" and carries no percentage, and where the households missing from a category are fewer than ten the text says "nearly all". The "Answered" counts beside the "Applies" counts still show how many households did not answer each question, often fewer than ten; a question left unanswered is not a trait of the household, so that is accepted here. Since the edition of 21 October 2026 the counts by group read "not shown" for the two questions on health spending, because health is not crossed with place anywhere in the review, and for the six dollar variables, whose empty cells mark the households that arrived in 2016 (fewer than ten in each group) and would give that number next to the row for the year of arrival; the three rows derived from them (logIncomeJordan, logExpensesJordan, ExpIncratio) read "not shown" for the same reason.
A5: Answered | B5: A household counts as having answered if the cell is not empty. Percentages are computed over the households to which the question applies ("Applies" columns).
A6: Units | B6: Amounts in Jordan are in Jordanian dinars (JD) per month; amounts in Syria are in Syrian pounds. The scales keep the range of the question (1 to 5 or 1 to 10).
A7: Only where applicable | B7: Questions filled in only when there is something to report (second source of income, second contact). The number of households that answered is shown, without a percentage.
A8: Blanks | B8: The column "A blank means" records what the file alone can tell. The rule adopted after this audit (8 October 2026) is that a blank is a missing value and not a zero; the later steps of the review follow it.
A9: Original questions | B9: The 151 columns of the coded questionnaire, plus the two types of work of the father and the mother, which came from a separate file (typesofjobs.dta). The other 122 variables were built by the do-file.
A10: Verification | B10: The counts moved from the computer to this table as a text of 275 lines, with the same md5 checksum, a fingerprint of the file (0dac79f1edc7ce5c0dd2df3fb63ed8d1), on both sides. The analysis file was compared cell by cell with the original CSV.
A11: Blind replication | B11: On 9 October 2026 a separate instance of the AI assistant that prepared this review, given only written definitions and no code or results, recomputed the 275 lines from the analysis file: the text came out identical, with the same checksum. It also repeated the comparison of the two files (same result) and seventeen checks behind the findings (72 values). Two findings were corrected as a result: the range expected under a random interview order (89 to 108, not 88 to 107), and the finding on the first contact, which had given the figure for the whole sample as that of the towns.
A12: Independent review | B12: On 9 October 2026 two further instances that had produced none of the files reviewed this workbook and its chart as a reader receives them: every count matched the 275 lines and every formula was right. They found sentences where two counts side by side gave away a count below ten, a few labels and names not yet aligned with the other workbooks, and one figure (the voucher amount among camp households that report assistance only) that no script of the audit produced. The edition of 13 October 2026 reworded those sentences, aligned the names (the second group is the northern towns; the scales are self-rated integration), and added the script a6_vale_solo_asistencia.py, run on the author's computer on 13 October 2026, which confirms the figure.
... A14: What is missing | B14: The original questionnaire and the date of each interview are not in the folder. The descriptions in the "What it measures" column come from the labels in the file, the documents from 2016 and 2017 and the do-files.
