Workbook

Sheet Verdicts
A1: Step 5 of the review: what the published page says, claim by claim, and what the review supports
A2: The page is the visual essay "Encampment, Self-Settlement and the Recovery of Displaced Households: Syrian Refugees in Jordan" (index.html, with the Spanish version index_espanol.html, which carries the same figures). Each row is one claim of the page, in the order of the page, read against the four earlier steps of the review: step 1 (what the survey measures well), step 2 (whom the sample represents), step 3 (the theory of change) and step 4 (design 1, the shocks family, the decomposition, the four indices and the flexible-estimation check). Abbreviations in the "Where in the review" column: S1 = encampment_variable_audit.xlsx; S2 = encampment_sample_and_benchmarks.xlsx; S3 = encampment_theory_of_change.xlsx; S4 = encampment_design_diagnostics.xlsx (seventh edition); "step 2 profile" = the profile of the two groups behind steps 2 and 3 (script b1_profile.py, aggregate file b1_profile.min.json), cited where a figure sits in that aggregate and is not printed on a sheet; "step 5b" = the descriptive cuts declared in review/brief_5b.md on 21 October 2026 (the composition of reported spending, the rent burden and income after rent, the responses by thirds of the rent burden, the average day by group and sex of the respondent), computed on the author's computer (aggregate file out_c7.json), replicated blind and printed in the technical note (encampment_technical_note.ipynb, Tables 4.4 to 4.6 and 7.10). A count below ten that the page itself prints is masked here in square brackets.
A3: Five verdicts, fixed before the claims were read against the review. Holds: the review confirms the figure and the reading. Holds with new wording: the fact holds and the wording changes for the rules fixed for the review (no effects, the names decided, the lexicon, households as the subject of each sentence, protection of small counts). Revise: the review gives another number or another reading and the claim changes in substance. Not supported: the review contradicts it or the data cannot carry it, so it goes. Not checked: the review did not test it, and the row says what it would take. Two flags beside the verdict: protection (the sentence prints, or lets a reader work out, a count below ten households) and language (a causal verb, a place as the subject, a name not agreed, the word the author avoids, a headline wider than its figure, or a statement that needs its source named). The last column gives the part of the chain of the step 3 workbook that the claim belongs to.
A5: No. | B5: Chapter | C5: Where on the page | D5: What the page says | E5: What the review found | F5: Where in the review | G5: Verdict | H5: Wording proposed for the page | I5: Protection flag | J5: Language flag | K5: Part of the chain
A6: Title, lead and map
A7: 0.1 | B7: 0 | C7: Lead paragraph | D7: The same 391 families described their lives in Syria before the war and in Jordan in 2016; inside Zaatari camp and outside it, Jordan hosted them under two different sets of rules; the page tells what each family lost, what it rebuilt, and why. | E7: The counts hold (257 households interviewed in Zaatari camp, 134 in northern towns). The pre-war module covers resources and traits (income, goods, savings, debts, business, car, pension, vacations, housing, schooling), not the responses, the scales or the shocks, so the page can speak of a pre-war module rather than of the same questionnaire asked twice. "Why" promises causes; the review found no causal design in the data (no instrument, no discontinuity, no cohort structure), so the page can show what goes with living in each place, not what each place did. | F7: S4 How it was done (rows 3 and 4); S1 Variables (the blocks on Syria); S3 How it was done | G7: Holds with new wording | H7: Between June and August 2016, 391 Syrian refugee households were interviewed in Jordan, 257 in Zaatari camp and 134 in northern towns. Each household also described its resources in Syria before the war. The two groups lived under different rules in Jordan, and the page shows what households in each setting lost, what they rebuilt, and what went with each outcome. | J7: causal promise ("why") | K7: 0
A8: 0.2 | B8: 0 | C8: Map caption | D8: Three in four households came from Daraa governorate, just across the border (Daraa city about 12 km from Ramtha); lines are drawn only for origin and destination pairs with at least 5 households (353 of the 380 households with a recorded origin); 11 households did not record an origin. | E8: Daraa origin: 86% in the camp and 64% in the towns, about three in four of the 380 households with a recorded origin. Ramtha lies about 11 km from Daraa in a straight line (Tokmajyan 2021 gives some 10 km). The map rule (pairs of five or more) is the one decided on 21 October 2026. The figure changes: under the coding of origin of the step 2 profile, which the step 2 workbook and the map of the brief use, the lines drawn cover 351 of the 380 households with a recorded origin; the page's figure came from an aggregate of the map computed on 5 October 2026, which coded some places of origin differently (found by the check of coherence of 23 October 2026). The counts printed (351 of 380; 11 without origin) are at or above ten. | F8: S2 Comparison (No. 1, 2 and 24); S3 Checks, section 6 (distances); flows by origin and place of interview under the step 2 coding (map/m1_flujos.py, computed on the author's computer on 23 October 2026) | G8: Revise | H8: The caption with 351 in place of the page's figure. One check remains in the HTML of the page: the hover shows counts by governorate of origin at each destination, and a pair of five to nine households would print a count below ten; the rule agreed for the map (five or more) covers the lines drawn, and the counts shown should follow the same rule, stated on the page, or the ten rule. The brief that replaces the page shows the width class in its hover and prints counts for the two largest flows to the camp only. | I8: hover counts by governorate of origin to be checked in the HTML | K8: 0
A9: 0.3 | B9: 0 | C9: Lead, chapter 1 and methods | D9: Fieldwork took place between May and July 2016. | E9: The two documents of 2016 and 2017 in the folder say June and July 2016; the file holds no interview date (16 records of the raw sheet carry one date, in August 2016); Ramadan ran from 6 June to 5 July 2016. Author's account (21 October 2026): fieldwork ran from June to August 2016, which the dated records of the raw sheet fit. The step 1 finding is to be updated in the next edition of that workbook. | F9: S1 Findings (No. 1 and 2); author's account, 21 October 2026 | G9: Revise | H9: Between June and August 2016 (and, in the methods section, the same months in place of May to July). | K9: 0
A10: Chapter 1. The households
A11: 1.1 | B11: 1 | C11: Chapter 1, opening | D11: 391 households: 257 in the twelve districts of Zaatari camp and 134 in Irbid, Ramtha, Jerash, Zarqa and the towns around them. | E11: Holds: 257 camp households spread over the twelve districts like the REACH count of January 2015; 134 towns households (52 in Irbid, 38 in Ramtha, 24 in Jerash, 10 in Zarqa and fewer than ten in three other places). | F11: S2 Places and districts; S2 Findings (No. 1 and 6) | G11: Holds | H11: No change. The page can add, once, that two thirds of the towns group live in Irbid and Ramtha, the two cities nearest to Daraa, and that the results do not extend to Amman, where a third of all Syrians lived (fewer than ten households in the sample). | K11: 0
A12: 1.2 | B12: 1 | C12: Chapter 1, unit chart | D12: Every household answered the same questionnaire twice over: about its life in Jordan, and about its life in Syria before the war. | E12: Overstated. The Syria module records resources and traits before the war (income, durable goods, savings, debts, loans, business, car, pension, vacations, outings, housing tenure, informal work); the shocks, the eleven responses, the scales, security and assistance were asked for Jordan only. The review uses the Syria answers as pre-war traits for the comparison, not as a second wave. | F12: S1 Variables (blocks on Syria); S3 Theory of change, part 8 (column H); S4 Verdict (sample note) | G12: Revise | H12: Each household also answered a module on its resources in Syria before the war: income, durable goods, savings, debts, business, car, pension and housing. Those answers describe the household before displacement and serve to compare like with like. | K12: 0
A13: 1.3 | B13: 1 | C13: Chapter 1, unit chart | D13: Inside the camp: registration, food vouchers, a caravan and almost no work. Outside: movement, informal work and rent. | E13: "Almost no work" overstates: 36% of camp households name work income among their sources and 39% name a member who works (67% and 64% in the towns). Among comparable households the work-income difference is 24 points (robust). Rent: 87% of towns households rent (median JD 130, Jordanian dinars); fewer than ten camp households do. | F13: S3 Figures; S2 Findings (No. 8); S4 Verdict (income from work) | G13: Revise | H13: Inside the camp: registration, a caravan, the food voucher for nine households in ten, and work income in about one household in three. In the towns: movement, work income in two households of three, and rent for nearly nine in ten. | K13: 1
A14: 1.4 | B14: 1 | C14: Chapter 1, unit chart (routes out of the camp) | D14: The 134 households outside the camp got there in different ways: 49 never entered a camp; 42 left Zaatari with a Jordanian sponsor, the legal route until 2015; [a count] left informally; [a count below ten] left with a permit or did not say. | E14: The page prints a count below ten, and the three other counts let a reader work it out by subtraction. Of the 134 towns households, 84 passed through a camp (71 lived in Zaatari and 13 in Azraq, so "left Zaatari" is not exact), 42 report leaving with a sponsor and most of the rest informally; the other routes have fewer than ten households. Households that left with a sponsor weigh more in the sample than in the UNHCR estimate (27% of exits). The page's 49 that never entered a camp and the review's 84 that passed through one do not partition the 134 the same way (the review's base is the households that report having passed through a camp), so the two figures are not combined. | F14: S2 Comparison (No. 32 and 33); S2 Findings (No. 14); S3 Theory of change, part 0 (column F) | G14: Holds with new wording | H14: Of the 134 households in the towns, 84 passed through a camp and 50 did not. Of those 84, 42 report leaving with a Jordanian sponsor, the legal route until 2015, and the other 42 left informally, by another route, or did not say how. Households that left with a sponsor weigh more in this sample than among all exits from Zaatari. | I14: prints a count below ten; the four counts add to the group total | K14: 0
A15: 1.5 | B15: 1 | C15: Chapter 1, unit chart | D15: How a family left later decided which documents it could hold. | E15: A statement about the rules, not about the survey, and the sources support it: from July 2014 households that left a camp without a sponsor could not obtain the Ministry of Interior card, and the sponsor route was suspended in January 2015 (NRC and IHRC 2016). The survey did not ask about the card. | F15: S3 Literature (NRC and IHRC 2016); S3 Theory of change, part 0 (columns G and H) | G15: Holds with new wording | H15: Under the rules of the time, the route out of a camp decided which documents a household could later hold: those that left without a sponsor after July 2014 could not obtain the Ministry of Interior card (NRC and IHRC 2016). The survey did not ask about the card. | J15: cite the source in the sentence | K15: 0
A16: 1.6 | B16: 1 | C16: Chapter 1, unit chart (registration) | D16: The survey never asked about Ministry of Interior cards. It did ask about UNHCR registration: [a total that fixes a camp count below ten] households were still waiting to be registered, twelve of them outside the camp, most of them recent arrivals or families that never entered a camp; the ring marks them. | E16: The two counts leave a count below ten for the camp by subtraction, the ring marks those households one by one on the chart, and "most of them recent arrivals or families that never entered a camp" cuts the twelve into cells below ten. Twelve towns households and fewer than ten camp households reported being asylum seekers; none reported being unregistered. There is no variation to compare. The sentence under the chart, that no dot is an identifiable household, holds once the ring goes. | F16: S1 Findings (No. 14); S2 Comparison (No. 28); S2 Findings (No. 17) | G16: Holds with new wording | H16: The survey never asked about Ministry of Interior cards. It did ask about UNHCR registration: twelve households in the towns, and fewer than ten in the camp, reported being asylum seekers still awaiting registration; none reported being unregistered. (The ring on the chart goes, and the cut of the twelve by arrival and camp history goes with it.) | I16: camp count below ten by subtraction; the twelve cut into cells below ten; the chart marks them | K16: 0
A17: 1.7 | B17: 1 | C17: Chapter 1, unit chart (who answered) | D17: Women answered 63 percent of the interviews outside the camp and 21 percent inside, the largest difference between the two samples; every subjective answer on the page is read with that in mind. | E17: Holds: a woman answered in 63% of towns households and 21% of camp households (standardized difference 0.8 to 0.9, as large as any in the data; urban origin reaches 0.89 too). The review reports the three scales within each sex of the respondent and finds the integration difference among men and among women alike, the optimism difference among women only. | F17: S2 Findings (No. 12 and 13); S4 Within sex | G17: Holds | H17: No change. | K17: 0
A18: 1.8 | B18: 1 | C18: Chapter 1, unit chart (eating less) | D18: Asked how they had coped with a fall in income, 73 percent of households outside the camp said they had eaten less, against 55 percent inside. | E18: Holds as a description of all households: 73% and 55%. Among comparable households (same pre-war traits, within the common support) the difference is 7 to 15 points and cannot be told from zero; the raw gap comes in good part from the traits that also decided where the household lives; the lower incidence of the shock in the towns works against the gap, and the response given the shock accounts for it (for the consumption cuts index, over all households, the incidence part is -0.11 and the part given the shock +0.47). | F18: S3 Figures; S4 Verdict and Shocks verdict (ate less); S4 Decomposition | G18: Holds with new wording | H18: Asked how they had coped with a fall in income, 73 percent of households in the towns said they had eaten less, against 55 percent in the camp. Among households with the same pre-war traits the gap is far smaller (7 to 15 points) and cannot be told from zero. | K18: 4
A19: 1.9 | B19: 1 | C19: Chapter 1, closing | D19: Households with more income cut food more often. The rest of the page explains why, and what it would have taken to change it. | E19: The premise weakens among comparable households (see 1.8). What the review can say: the shock (a fall in income) was less frequent in the towns (78% against 92%; 21 points fewer among comparable households, robust); among comparable households that suffered it, towns households cut consumption more (ate less 21 points more, cut other spending 25 points more) and drew less on savings and loans (17 and 20 points fewer), with no difference in the severe responses. Those conditional figures are descriptive. "What it would have taken to change it" is a causal counterfactual the design cannot support. | F19: S4 Decomposition (block B); S4 Shocks verdict; S4 How it was done (row 3) | G19: Revise | H19: Households in the towns have more income and more often report having eaten less. The rest of the page shows what goes with that: fewer of them suffered a fall in income, but among comparable households that did, more cut consumption and fewer drew on savings or loans. | J19: causal counterfactual | K19: 4
A20: Chapter 2. Before and after
A21: 2.1 | B21: 2 | C21: Chapter 2, opening | D21: Because every question was asked for Syria as well as for Jordan, the survey can be read as a two-period panel of the same household. | E21: Not supported. The survey is a single cross-section with recalled pre-war traits; each household is seen once, and matching on those traits or holding the year of arrival equal does not change that (step 3, part 8). Not every question was asked for Syria (see 1.2), the pre-war answers are recalled, and two of them carry gaps: income in Syria has no amount for 19 towns households (zero in the thesis variable) and spending in Syria none for 30. | F21: S3 Theory of change, part 8 (column H); S1 Findings (No. 15); S1 Variables | G21: Not supported | H21: The survey is a single cross-section taken in 2016. Its module on Syria before the war, answered from memory, gives the pre-war traits on which households are compared and a before-and-after picture of a few items (income, goods, savings, debts, work) that is read as recall, not as a second wave. | J21: "panel" | K21: 8
A22: 2.2 | B22: 2 | C22: Chapter 2, income before and after | D22: At one pre-crisis rate for everyone, camp households went from $465 a month to $220 and households outside from $495 to $384. | E22: The Jordan figures come close to the mean reported incomes (JD 162 in the camp and JD 277 in the towns, which at the page's rate of 1.405 give about $227 and $390). The Syria figures were not reproduced: the review keeps incomes in Syria in pounds (medians of 20 and 24 thousand a month; means of 26 and 32 thousand) because the conversion and the handling of blanks drive the dollar figures (19 towns households with no amount appear as zero in the thesis variable; the dollar variables of the thesis are empty where the year of arrival is missing or is 2016). The direction holds: camp households report the larger loss. | F22: Step 2 profile (means and medians of household income); S2 Before the war; S1 Findings (No. 15 and 16); S2 Findings (No. 16) | G22: Not checked | H22: Keep only after recomputing with blanks as missing and the pre-crisis rate stated, and report medians beside the means. Otherwise: in Syria the two groups reported similar incomes (medians of 20 and 24 thousand pounds a month); in Jordan the median is JD 140 a month in the camp and JD 270 in the towns. | K22: 1
A23: 2.3 | B23: 2 | C23: Chapter 2, income before and after | D23: Four in five camp households lost income; fewer than half outside did. | E23: Contradicted by the direct question: 92% of camp households and 78% of towns households report that their income fell since arrival, and the difference among comparable households is 21 to 25 points (robust). The page itself later counts 103 towns households that gave a cause for the fall. The computed version (converted amounts) depends on the conversion and on the blanks. | F23: S3 Figures; S4 Shocks verdict (income fell); S3 Theory of change, part 4 | G23: Revise | H23: Asked directly, 92 percent of camp households and 78 percent of households in the towns said their income had fallen since arrival; among comparable households the difference is about 21 points and holds under every test. | K23: 4
A24: 2.4 | B24: 2 | C24: Chapter 2, income before and after | D24: The thesis converted each family's income at the rate of the year it left Syria; read that way camp households lose little and households outside gain; since nominal pound incomes are the same across departure cohorts, this rate mostly records when a family left; it stays in the appendix. | E24: A methodological note the review did not test. One limit bears on it: the year of arrival is missing for 23 camp households and the month for 317 of 391, so an exit-year rate is undefined or coarse for many households. | F24: S1 Findings (No. 13 and 16) | G24: Not checked | H24: Keep as a note, adding that the year of arrival is missing for 23 camp households and the month for most households, so a rate by year of exit is undefined for some and coarse for the rest. | K24: 1
A25: 2.5 | B25: 2 | C25: Chapter 2, income before and after | D25: At purchasing power parity, households outside the camp are back at their pre-war standard of living and camp households are at about 60 percent of theirs; the factors are provisional, but the ranking does not depend on them. | E25: Not tested in the review, and subject to the same blanks and conversion caveats as 2.2. | F25: S1 Findings (No. 15 and 16) | G25: Not checked | H25: Keep only with the recomputation of 2.2; the ranking (a larger loss in the camp) is consistent with the pound and dinar figures. | K25: 1
A26: 2.6 | B26: 2 | C26: Chapter 2, income before and after | D26: Incomes in Syria were nearly identical (a standardised difference of 0.06), so the difference in within-household changes is about the same as the raw 2016 gap: $134 a month at the fixed rate, with a standard error of $61; the income advantage of households outside the camp was not inherited from Syria. | E26: The first part holds: recalled income in Syria hardly separates the groups (medians of 20 and 24 thousand pounds; the same median per person, 5 thousand). The $134 and its standard error were not reproduced (see 2.2). The design did not estimate the income level; it finds work income 24 points more frequent and spending per person about 1.9 times as high among comparable towns households (both robust). | F26: S2 Before the war; S2 Findings (No. 16); S4 Verdict (income from work; spending per person) | G26: Revise | H26: Recalled incomes in Syria hardly separate the two groups (medians of 20 and 24 thousand pounds a month), so the gap in Jordan was not inherited from Syria. Among comparable households, towns households more often have work income (24 points) and spend about 1.9 times as much per person. | K26: 1
A27: 2.7 | B27: 2 | C27: Chapter 2, goods chart (headline) | D27: Camp households lost the kitchen; households outside rebuilt it. | E27: The two goods hold as basic living conditions reached in Jordan: a refrigerator in 44% of camp households and nearly all in the towns; a stove in 23% and 74%. "Lost the kitchen" goes beyond the appliance count: cash for gas went to all camp families (REACH 2017), 82% of camp households had a separate kitchen in 2017 and 2018 (Fafo), and camp households cooked at home with gas while 23% report a stove, so the question appears to have counted the appliance. Use decided on 9 October 2026: report the two goods separately, as conditions reached in Jordan, and do not say camp households could not cook. | F27: S3 Checks, section 7; S3 Theory of change, part 5 | G27: Holds with new wording | H27: Fewer camp households have a refrigerator and a stove today; in the towns nearly all have a refrigerator and three in four a stove. | J27: headline says more than the count | K27: 5
A28: 2.8 | B28: 2 | C28: Chapter 2, goods chart | D28: Almost every household owned a refrigerator and a stove in Syria. In Zaatari fewer than one in four has a stove and fewer than half a refrigerator, because the caravan came without a kitchen; outside the camp, ownership of both is back near Syrian levels. | E28: The Syria figures hold (more than nine in ten households had each good) and the camp figures hold (23% and 44%). "Back near Syrian levels" holds for the refrigerator (nearly all) and not for the stove (74% against more than nine in ten in Syria). "Because the caravan came without a kitchen" is an explanation the survey does not test (see 2.7); the electricity supply (nine hours a day after 14 July 2016) bears on what a refrigerator was worth in the camp. | F28: S3 Checks, section 7; S3 Figures; S3 Literature (REACH 2016, AP 2016) | G28: Revise | H28: More than nine in ten households had a refrigerator and a stove in Syria. In Zaatari, 23 percent have a stove today and 44 percent a refrigerator; in the towns nearly all have a refrigerator and 74 percent a stove. Among comparable households the differences are 44 to 47 points for the stove and 30 to 40 for the refrigerator, and they hold under every test. | K28: 5
A29: 2.9 | B29: 2 | C29: Chapter 2, goods chart | D29: Counting four durable goods, camp households went from 3.3 items to 1.6 and households outside from 3.4 to 2.7. | E29: Not reproduced. The use decided on 9 October 2026 keeps the goods out of any wealth index between the camp and the towns, because much of what a household can hold depends on the place (electricity, space, what is provided in kind), and reports the refrigerator and the stove separately. The television (90% in the camp, nearly all in the towns) and the car (fewer than ten households in each group today) add little. | F29: S3 Checks, section 7 (use decided, point 2); S2 Before the war; step 2 profile (television and car today) | G29: Not supported | H29: Drop the count of items; report the refrigerator and the stove as in 2.8. | K29: 5
A30: 2.10 | B30: 2 | C30: Chapter 2, savings | D30: Half of the households later found outside the camp had savings in Syria, against fewer than one in five of those who stayed; by 2016 both groups were at [a share built on fewer than ten households]. | E30: The Syria figures hold (50% and 18%). The 2016 share rests on fewer than ten households in each group, so it cannot be printed as a percentage; the review states it as "fewer than ten in each group". | F30: S2 Before the war; S3 Checks, section 3; S2 Findings (No. 16) | G30: Holds with new wording | H30: Half of the households later found in the towns had savings in Syria, against fewer than one in five of those in the camp; by 2016 fewer than ten households in each group reported any savings. | I30: a share built on counts below ten | K30: 4
A31: 2.11 | B31: 2 | C31: Chapter 2, debt | D31: Debt rose from about a quarter of households to 60 percent in the camp and 69 percent outside, and since formal loans are nearly absent in Jordan, that debt is owed to shops, relatives and landlords. | E31: The shares hold (24% and 26% in Syria; 60% and 69% today; among comparable households 12 to 22 points more in the towns, fragile). The survey records no amount and no lender, so "owed to shops, relatives and landlords" rests on other studies: about 80% of indebted households owe to relatives and friends in Jordan (Fafo 2017-2018); refugees borrow mainly from neighbours (CARE 2017). Loans in Jordan are reported by fewer than ten households in each group. | F31: S3 Figures; S3 Theory of change, part 4 (columns D and G); S4 Verdict (has debts); S2 Before the war; step 2 profile (loans in Jordan) | G31: Holds with new wording | H31: Debt rose from about a quarter of households in Syria to 60 percent in the camp and 69 percent in the towns. The survey did not ask to whom; other surveys in Jordan find the debt owed mostly to relatives, friends and neighbours (Fafo 2017-2018; CARE 2017). | J31: cite the sources for the lender | K31: 4
A32: 2.12 | B32: 2 | C32: Chapter 2, work | D32: Work collapsed and recovered unevenly: nearly every household had an earner in Syria; in 2016, 39 percent of camp households did, mostly in incentive positions with NGOs and short weeks, against 64 percent outside, where those who work put in longer weeks than they did in Syria. | E32: The two shares hold as "a member works": 39% and 64% (work income among the sources: 36% and 67%; among comparable households 24 points more in the towns, robust). "Mostly in incentive positions with NGOs" and the comparison of weekly hours were not checked: the occupation labels are the respondent's, hours are usable with care, and the small occupation cells would need a protection pass. | F32: S1 Findings (No. 10); S3 Checks, section 2; S4 Verdict (income from work) | G32: Holds with new wording | H32: Nearly every household had an earner in Syria. In 2016 a member works in 39 percent of camp households and 64 percent of households in the towns; among comparable households the difference in work income is about 24 points and holds under every test. (The sentences on incentive positions and on weekly hours stay only after a check of the occupation and hours answers under the protection rule.) | K32: 1
A33: Chapter 3. Who left the camp
A34: 3.1 | B34: 3 | C34: Chapter 3, opening | D34: Until 2015 the legal way out of Zaatari was a Jordanian sponsor, which took means and contacts; the pre-displacement module lets the reader see directly what separated the two groups before anyone crossed the border, and it looks exactly like that. | E34: The rule is supported by the sources: the sponsor route was suspended in January 2015 (NRC and IHRC 2016); Zaatari residents could leave with a Jordanian relative as sponsor (Tobin et al. 2021). Households that left with a sponsor are over-represented in the sample (42 of 84 that passed through a camp, against 27% of exits in the UNHCR estimate). The module shows the means (savings, business, car, pension) and not the contacts: the survey did not ask whether the household had relatives or acquaintances in Jordan. | F34: S3 Literature; S2 Findings (No. 14); S3 Theory of change, part 0 (column H) | G34: Holds with new wording | H34: Until 2015 the legal way out of Zaatari was a Jordanian sponsor, which took means and contacts (NRC and IHRC 2016; Tobin et al. 2021). The module on Syria shows the means directly; the survey did not ask about contacts in Jordan. | K34: 0
A35: 3.2 | B35: 3 | C35: Chapter 3, balance chart | D35: Income in Syria, home ownership, household size, the respondent's age and the year of arrival are balanced. What differs is liquidity and origin: households now outside the camp had savings and a car far more often, came from towns rather than villages, had finished secondary school more often, and came less often from Daraa. | E35: Holds, with two traits missing from the list: an own business in Syria (37% and 65%) and a pension in Syria (fewer than ten camp households; 22% in the towns), which weigh in the selection model (odds ratios 3.5 and 6.9) beside urban origin (7.7) and savings (5.7). The balanced traits hold: income in Syria (medians 20 and 24 thousand pounds), owned home (92% in the camp and nearly all in the towns), household size (5.0 and 5.1), age (means 38.6 and 39.8), arrival by 2012 (44% and 46%). Schooling is the respondent's, not the head's. The page reads 0.25 as the threshold of imbalance; the Balance sheet of the review uses 0.1. | F35: S2 Before the war; S2 Findings (No. 16); S4 Sample and overlap (logit coefficients); S4 Balance | G35: Holds with new wording | H35: Add own business (37 against 65 percent) and pension in Syria (fewer than ten camp households against 22 percent in the towns) to the traits that differ, and say that schooling is the respondent's. | K35: 0
A36: 3.3 | B36: 3 | C36: Chapter 3, balance chart | D36: Selection into leaving the camp ran through the ability to arrange an exit, not through earning capacity. That is the selection the analysis has to absorb, and the pre-displacement outcomes make the adjustment testable: whatever reweighting works should leave no difference on life in Syria. | E36: The direction holds: the pre-war traits predict the place of residence well (area under the curve 0.87 for the nine-trait logit), urban origin and savings in Syria lead, and flexible models find no interaction the logit misses (0.85 against 0.85). "Not through earning capacity" rests on recalled income only, which has no amount for 19 towns households. The placebo on life in Syria was not reproduced; the review's placebo is different: six pre-war traits left out of the design barely predict residence (0.56) and, within the support with the weights, hardly at all (0.54 to 0.57); the placebo itself is settled in row 4.11. | F36: S4 Sample and overlap; S4 Flexible estimation (selection model and placebo); S1 Findings (No. 15) | G36: Holds with new wording | H36: What separated the two groups before the war was liquidity and origin (savings, a business, a pension, urban origin), not recalled income. Those traits predict where a household lives well, and six pre-war traits left out of the design add almost nothing, which is the check the comparison rests on. | K36: 0
A37: 3.4 | B37: 3 | C37: Chapter 3, closing | D37: The largest difference of all is who answered the questionnaire. | E37: Holds (see 1.7): standardized difference 0.8 to 0.9. | F37: S2 Findings (No. 12); S4 Within sex | G37: Holds | H37: No change. | K37: 0
A38: Chapter 4. After adjustment
A39: 4.1 | B39: 4 | C39: Chapter 4, opening | D39: Outcomes are grouped into seven domains, each an index in standard deviations of the camp and signed so that higher is better; camp households are reweighted so that their pre-displacement means match those of out-of-camp households. | E39: Replaced by the declared design. The uses decided on 9 October 2026 keep self-rated integration apart from happiness and optimism, the refrigerator and the stove out of any wealth index, the security scale read by its distribution, and the responses one by one with four declared indices (consumption cuts, financial buffers, severe responses, WFP severity score). Design 1 compares outcome levels between towns households and camp households with the same nine pre-war traits, within the common support (116 camp and 95 towns households), with augmented inverse probability weighting (AIPW) as the main estimator and four others as checks. | F39: S4 Verdict (header); S4 How it was done; S3 Checks, sections 7 and 8; S4 Indices | G39: Revise | H39: Twelve outcomes and the shocks and responses are compared one by one between towns households and camp households with the same pre-war traits (urban origin, savings, business, car, pension, vacations and origin in Daraa, household size, arrival by 2012), within the region where the two groups overlap. The scales and the two basic living conditions are reported in their own units; four declared indices summarise the responses. | K39: 0
A40: 4.2 | B40: 4 | C40: Chapter 4, title and throughout | D40: What living outside the camp did; the effect of living outside the camp. | E40: No causal design is available: the data hold no instrument, no discontinuity, no measure before displacement of the outcomes and no cohort structure that would separate the place from the households who chose it. Every figure of the review is a difference between comparable households, towns minus camp. | F40: S4 How it was done (row 3); S4 Verdict (header) | G40: Not supported | H40: Replace "effect of living outside the camp" everywhere by "difference between comparable households, towns minus camp", and say once that none of the differences is an effect of living in one place or the other. | J40: causal wording throughout the chapter | K40: 0
A41: 4.3 | B41: 4 | C41: Chapter 4, raw differences | D41: The raw differences are large in both directions: households outside the camp have more income, more assets and more work, and report much lower wellbeing, weaker social ties and less security. | E41: Income, spending, work and the two goods hold. "Wellbeing": self-rated integration 8.0 against 4.8 holds; optimism 6.1 against 5.1 and happiness 5.0 against 4.5 are smaller. "Social ties": the survey has no network measure beyond the first contact in an emergency (family or relatives 22% in the camp and 51% in the towns). "Less security" is not what the direct question shows: good or very good personal security is reported by 71% in the camp and 86% in the towns, very good by 52% and 33%; theft by 22% in the camp and fewer than ten towns households. | F41: S3 Theory of change, parts 6 and 7; S3 Checks, sections 1 and 8; S3 Figures | G41: Revise | H41: Before any adjustment, households in the towns have more income, more work and more of the two basic living conditions; they rate their integration far lower (4.8 against 8.0 on the 1 to 10 scale) and are somewhat less optimistic; on security the picture is mixed: more of them rate it good or very good, fewer rate it very good, and fewer report a theft. | K41: 6
...

Sheet By part of the chain
A1: The nine parts of the chain: what claim each one supports (the column left open in the step 3 workbook)
A2: The parts are those of the Theory of change sheet of the step 3 workbook (encampment_theory_of_change.xlsx), whose column I said "settled in step 5 of the review". Robust, Fragile and Null are the tiers of the step 4 workbook (Verdict, Shocks verdict and Indices sheets), under the rule fixed before the numbers were read: Robust when the Romano-Wolf p is at or below 0.05, the AIPW t at or above 1.96 in absolute value, the robustness value for significance at or above 0.05 and the five adjusted estimators share the sign; Null when the OLS design-based p is above 0.10 and the AIPW t below 1.96; Fragile otherwise. Figures are differences between comparable households, towns minus camp, within the common support; none is an effect of living in one place or the other. The last column counts the rows of the Verdicts sheet assigned to the part.
A4: No. | B4: Part of the chain | C4: What claim it supports | D4: Results the paper can lean on, by tier | E4: Rows of the Verdicts sheet | F4: Rows (count)
A5: 0 | B5: Before the war and where the household ended up | C5: Comparative description, with a selection model behind it. Households now in the towns differed before the war in liquidity and origin: urban origin (22% in the camp, 60% in the towns), savings in Syria (18% and 50%), own business (37% and 65%), a pension (fewer than ten camp households; 22% in the towns), less often an origin in Daraa (86% and 64%); not in recalled income (medians of 20 and 24 thousand pounds). The nine pre-war traits predict the place of residence well (area under the curve 0.87), flexible models find no interaction the logit misses (0.85 against 0.85), and six pre-war traits left out of the design barely predict it (0.56; 0.54 to 0.57 within the support with the weights). The sample over-represents households that left the camp with a sponsor. | D5: Description (step 2 and the selection model of step 4). | E5: 0.1, 0.2, 0.3, 1.1, 1.2, 1.4, 1.5, 1.6, 1.7, 3.1, 3.2, 3.3, 3.4, 4.1, 4.2, 4.9, 4.11, 4.12, M.1, M.3, M.4, M.6, M.7, M.8, M.9 | F5: =COUNTIF(Verdicts!$K$6:$K$80,A5&"") -> 25
A6: 1 | B6: What comes into the household | C6: Among comparable households, towns households name work income among their sources 24 to 30 points more often (robust under the tier rule; fragile under the eight-trait specification; 32 points before adjustment). Assistance reaches nine households in ten in both groups, as two different packages: the voucher for 93% of camp households, at JD 20 per person for nine in ten of them, and no work income among the sources for 64% of camp households; in the towns a voucher in two tiers (median JD 10 per person), cut in August 2015, UNHCR cash for 30%, and no work income for 33%. The income level itself is described (medians of JD 140 and 270 a month), not estimated. | D6: Robust: income from work (+24 points). Description: the two assistance packages. | E6: 1.3, 2.2, 2.4, 2.5, 2.6, 2.12, 4.4, 5.3, 5.6, 5.14, M.5 | F6: =COUNTIF(Verdicts!$K$6:$K$80,A6&"") -> 11
A7: 2 | B7: What the household has to pay | C7: Comparable towns households spend about 1.9 times as much per person (0.63 log points, robust). What the spending covers differs by place: rent for 87% of towns households (median JD 130) and fewer than ten camp households; food spending per person about the same (means of JD 29 and 27; medians of JD 20). Reported spending, with blanks as missing (step 5b), is food in the camp (77% of the group total; a median share of 89% among the households that report it) and rent and food in the towns (35% and 33% of the total, with electricity, water and transport behind them; education is reported by fewer than ten households). Among the 104 towns households that rent with an income and a rent reported, rent takes 44% of reported income at the median (quartiles 31% and 63%) and income after rent is JD 32 per person a month at the median (mean 35, against a mean income per person of JD 38 in the camp, where fewer than ten households pay rent); the households with the heaviest rent burden ate less and carry debt more often (nearly all of the highest third). | D7: Robust: spending per person (+0.63 log points). Description: rent, food per person, the composition of reported spending and the rent burden (step 5b). | E7: 5.2, 5.4, 5.5, 5.7 | F7: =COUNTIF(Verdicts!$K$6:$K$80,A7&"") -> 4
A8: 3 | B8: The gap | C8: About half of households in each group report spending above income (45% and 50%); among comparable households the difference (9 to 17 points) cannot be told from zero, and the sample cannot detect one below about 25 points. Debts today are more frequent among comparable towns households (12 to 22 points), a fragile difference. | D8: Null: spending above income. Fragile: debts. | E8: 4.8 | F8: =COUNTIF(Verdicts!$K$6:$K$80,A8&"") -> 1
A9: 4 | B9: How the gap is closed | C9: Fewer towns households suffered a fall in income (78% against 92%; 21 to 25 points fewer among comparable households, robust). Comparable towns households drew on savings less often (22 to 26 points, robust) and on loans less often (19 to 21 points, fragile); the consumption cuts (7 to 17 points more in the towns: eating less null, cutting other spending fragile) and the number of responses used (fragile) do not clear the tests; the severe responses (education, child work, selling) do not differ. Given the shock, among comparable households that suffered it, towns households ate less 21 points more often and cut other spending 25 points more often, drew on savings 17 points less often and on loans 20 points less, with no difference in the severe responses. Read in the order of Corbett (1988) and van der Kam (2000), from the reversible responses (eating less, borrowing, drawing on savings) to the severe ones (cutting education, child work, selling belongings), the households with the shock in the towns stayed on the reversible rungs by eating less and cutting other spending where camp households borrowed and drew on savings, and neither group went further down the ladder than the other; a description of the households with the shock. The thesis estimate of 28 points for eating less does not survive the comparison of like with like. | D9: Robust: income fell (-21), used savings (-22). Fragile: loans, cut other spending, cut education spending, worked more hours, asked another member to bring income, number of responses, financial-buffers index. Null: ate less, a child went to work, sold belongings, asked for assistance, took a second job, severe responses index, WFP score. Description: the decomposition. | E9: 1.8, 1.9, 2.3, 2.10, 2.11, 4.10, 5.1, 5.8, 5.9, 5.10, 5.11, 5.12, 5.13 | F9: =COUNTIF(Verdicts!$K$6:$K$80,A9&"") -> 13
A10: 5 | B10: Basic living conditions: refrigerator and stove | C10: More towns households have reached the two conditions: a refrigerator 30 to 40 points more often and a stove 44 to 47 points more often among comparable households, the two largest differences among the yes or no outcomes of the twelve, and both keep their tier under the eight-trait specification and the sensitivity analyses; the differences also carry the conditions of each place (electricity, space, what is provided in kind). More than nine in ten households had each good in Syria. The step to nutrition and health is supplied by other studies. | D10: Robust: refrigerator (+30 to 40), stove (+44 to 47). | E10: 2.7, 2.8, 2.9, 4.5 | F10: =COUNTIF(Verdicts!$K$6:$K$80,A10&"") -> 4
A11: 6 | B11: Security | C11: No difference among comparable households in the share rating personal security good or very good (8 points, null); camp households give more answers at both ends of the scale (very good 52% against 33%; fair or worse 29% against 14%). Theft is reported by 22% of camp households and fewer than ten in the towns (not estimated). The first contact in an emergency differs: the police for 69% in the camp and 23% in the towns, family or relatives for 22% and 51%. "No one to turn to" is not usable (blank answers counted as "no one"). | D11: Null: personal security good or very good. Description: the distribution, theft, first contact. | E11: 4.3, 4.7 | F11: =COUNTIF(Verdicts!$K$6:$K$80,A11&"") -> 2
A12: 7 | B12: Community and morale | C12: Comparable camp households rate their integration about 3.2 points higher on the 1 to 10 scale, the difference with the highest robustness value of the twelve, among men and among women alike; the answer is reported under the name of the question and read as a sense of belonging or comfort where the household lives, with the shares at 1 to 3 and 7 to 10 beside the mean. Optimism is 1.1 to 1.7 points higher in the camp, a fragile difference carried by women respondents. Happiness cannot be told apart. In the towns, households that left the camp informally, by another route or without saying how rate their integration lower than those that left with a sponsor (4.0 against 5.7). An average day, as the respondent described it (step 5b): "nothing" is the answer of 63% of camp respondents and of none in the towns, where the day is taking care of the house (45%; 53% of the women and 32% of the men who answered) or sitting in the house (31%). | D12: Robust: self-rated integration (-3.2). Fragile: optimism. Null: happiness. Description: the average day (step 5b). Not checked: the average day by employment of the respondent, by district and against the scales (5.17 to 5.19). | E12: 4.6, 5.15, 5.16, 5.17, 5.18, 5.19 | F12: =COUNTIF(Verdicts!$K$6:$K$80,A12&"") -> 6
A13: 8 | B13: Over the years in Jordan | C13: Description of households that arrived in different years (more debt in both places among earlier arrivals and, among the goods, a stove in the towns and a refrigerator in the camp; the stove in the camp does not differ); the design holds arrival by 2012 equal between the groups and the path over time is not observed. No claim about trajectories. | D13: Description only. | E13: 2.1, M.2 | F13: =COUNTIF(Verdicts!$K$6:$K$80,A13&"") -> 2
E14: Total | F14: =SUM(F5:F13) -> 68
A16: How to read the tiers in the paper. The robust set (income from work, spending per person, refrigerator, stove, self-rated integration, income fell, used savings) is what the paper can state as a difference between comparable households that holds under every test. A fragile difference (debts, optimism, loans, cut other spending, number of responses, the financial-buffers index) can be reported with the test it fails named. A null difference is reported as such, with the minimum detectable difference beside it, because the sample cannot separate a small difference from zero.

Sheet Counts
A1: Verdicts by chapter
A2: The counts by chapter and the shares are formulas over the Verdicts sheet, so a changed verdict there changes the count here; the table of the robust results at the foot carries values copied from the step 4 workbook.
A4: Chapter | B4: Holds | C4: Holds with new wording | D4: Revise | E4: Not supported | F4: Not checked | G4: All claims | H4: Protection flags | I4: Language flags
A5: Title, lead and map | B5: =COUNTIFS(Verdicts!$B$6:$B$80,"0",Verdicts!$G$6:$G$80,"Holds") -> 0 | C5: =COUNTIFS(Verdicts!$B$6:$B$80,"0",Verdicts!$G$6:$G$80,"Holds with new wording") -> 1 | D5: =COUNTIFS(Verdicts!$B$6:$B$80,"0",Verdicts!$G$6:$G$80,"Revise") -> 2 | E5: =COUNTIFS(Verdicts!$B$6:$B$80,"0",Verdicts!$G$6:$G$80,"Not supported") -> 0 | F5: =COUNTIFS(Verdicts!$B$6:$B$80,"0",Verdicts!$G$6:$G$80,"Not checked") -> 0 | G5: =COUNTIF(Verdicts!$B$6:$B$80,"0") -> 3 | H5: =COUNTIFS(Verdicts!$B$6:$B$80,"0",Verdicts!$I$6:$I$80,"<>") -> 1 | I5: =COUNTIFS(Verdicts!$B$6:$B$80,"0",Verdicts!$J$6:$J$80,"<>") -> 1
A6: Chapter 1. The households | B6: =COUNTIFS(Verdicts!$B$6:$B$80,"1",Verdicts!$G$6:$G$80,"Holds") -> 2 | C6: =COUNTIFS(Verdicts!$B$6:$B$80,"1",Verdicts!$G$6:$G$80,"Holds with new wording") -> 4 | D6: =COUNTIFS(Verdicts!$B$6:$B$80,"1",Verdicts!$G$6:$G$80,"Revise") -> 3 | E6: =COUNTIFS(Verdicts!$B$6:$B$80,"1",Verdicts!$G$6:$G$80,"Not supported") -> 0 | F6: =COUNTIFS(Verdicts!$B$6:$B$80,"1",Verdicts!$G$6:$G$80,"Not checked") -> 0 | G6: =COUNTIF(Verdicts!$B$6:$B$80,"1") -> 9 | H6: =COUNTIFS(Verdicts!$B$6:$B$80,"1",Verdicts!$I$6:$I$80,"<>") -> 2 | I6: =COUNTIFS(Verdicts!$B$6:$B$80,"1",Verdicts!$J$6:$J$80,"<>") -> 2
A7: Chapter 2. Before and after | B7: =COUNTIFS(Verdicts!$B$6:$B$80,"2",Verdicts!$G$6:$G$80,"Holds") -> 0 | C7: =COUNTIFS(Verdicts!$B$6:$B$80,"2",Verdicts!$G$6:$G$80,"Holds with new wording") -> 4 | D7: =COUNTIFS(Verdicts!$B$6:$B$80,"2",Verdicts!$G$6:$G$80,"Revise") -> 3 | E7: =COUNTIFS(Verdicts!$B$6:$B$80,"2",Verdicts!$G$6:$G$80,"Not supported") -> 2 | F7: =COUNTIFS(Verdicts!$B$6:$B$80,"2",Verdicts!$G$6:$G$80,"Not checked") -> 3 | G7: =COUNTIF(Verdicts!$B$6:$B$80,"2") -> 12 | H7: =COUNTIFS(Verdicts!$B$6:$B$80,"2",Verdicts!$I$6:$I$80,"<>") -> 1 | I7: =COUNTIFS(Verdicts!$B$6:$B$80,"2",Verdicts!$J$6:$J$80,"<>") -> 3
A8: Chapter 3. Who left the camp | B8: =COUNTIFS(Verdicts!$B$6:$B$80,"3",Verdicts!$G$6:$G$80,"Holds") -> 1 | C8: =COUNTIFS(Verdicts!$B$6:$B$80,"3",Verdicts!$G$6:$G$80,"Holds with new wording") -> 3 | D8: =COUNTIFS(Verdicts!$B$6:$B$80,"3",Verdicts!$G$6:$G$80,"Revise") -> 0 | E8: =COUNTIFS(Verdicts!$B$6:$B$80,"3",Verdicts!$G$6:$G$80,"Not supported") -> 0 | F8: =COUNTIFS(Verdicts!$B$6:$B$80,"3",Verdicts!$G$6:$G$80,"Not checked") -> 0 | G8: =COUNTIF(Verdicts!$B$6:$B$80,"3") -> 4 | H8: =COUNTIFS(Verdicts!$B$6:$B$80,"3",Verdicts!$I$6:$I$80,"<>") -> 0 | I8: =COUNTIFS(Verdicts!$B$6:$B$80,"3",Verdicts!$J$6:$J$80,"<>") -> 0
A9: Chapter 4. After adjustment | B9: =COUNTIFS(Verdicts!$B$6:$B$80,"4",Verdicts!$G$6:$G$80,"Holds") -> 0 | C9: =COUNTIFS(Verdicts!$B$6:$B$80,"4",Verdicts!$G$6:$G$80,"Holds with new wording") -> 1 | D9: =COUNTIFS(Verdicts!$B$6:$B$80,"4",Verdicts!$G$6:$G$80,"Revise") -> 9 | E9: =COUNTIFS(Verdicts!$B$6:$B$80,"4",Verdicts!$G$6:$G$80,"Not supported") -> 2 | F9: =COUNTIFS(Verdicts!$B$6:$B$80,"4",Verdicts!$G$6:$G$80,"Not checked") -> 0 | G9: =COUNTIF(Verdicts!$B$6:$B$80,"4") -> 12 | H9: =COUNTIFS(Verdicts!$B$6:$B$80,"4",Verdicts!$I$6:$I$80,"<>") -> 0 | I9: =COUNTIFS(Verdicts!$B$6:$B$80,"4",Verdicts!$J$6:$J$80,"<>") -> 1
A10: Chapter 5. Why | B10: =COUNTIFS(Verdicts!$B$6:$B$80,"5",Verdicts!$G$6:$G$80,"Holds") -> 2 | C10: =COUNTIFS(Verdicts!$B$6:$B$80,"5",Verdicts!$G$6:$G$80,"Holds with new wording") -> 6 | D10: =COUNTIFS(Verdicts!$B$6:$B$80,"5",Verdicts!$G$6:$G$80,"Revise") -> 6 | E10: =COUNTIFS(Verdicts!$B$6:$B$80,"5",Verdicts!$G$6:$G$80,"Not supported") -> 2 | F10: =COUNTIFS(Verdicts!$B$6:$B$80,"5",Verdicts!$G$6:$G$80,"Not checked") -> 3 | G10: =COUNTIF(Verdicts!$B$6:$B$80,"5") -> 19 | H10: =COUNTIFS(Verdicts!$B$6:$B$80,"5",Verdicts!$I$6:$I$80,"<>") -> 4 | I10: =COUNTIFS(Verdicts!$B$6:$B$80,"5",Verdicts!$J$6:$J$80,"<>") -> 8
A11: Data, methods and limits | B11: =COUNTIFS(Verdicts!$B$6:$B$80,"M",Verdicts!$G$6:$G$80,"Holds") -> 1 | C11: =COUNTIFS(Verdicts!$B$6:$B$80,"M",Verdicts!$G$6:$G$80,"Holds with new wording") -> 3 | D11: =COUNTIFS(Verdicts!$B$6:$B$80,"M",Verdicts!$G$6:$G$80,"Revise") -> 3 | E11: =COUNTIFS(Verdicts!$B$6:$B$80,"M",Verdicts!$G$6:$G$80,"Not supported") -> 1 | F11: =COUNTIFS(Verdicts!$B$6:$B$80,"M",Verdicts!$G$6:$G$80,"Not checked") -> 1 | G11: =COUNTIF(Verdicts!$B$6:$B$80,"M") -> 9 | H11: =COUNTIFS(Verdicts!$B$6:$B$80,"M",Verdicts!$I$6:$I$80,"<>") -> 2 | I11: =COUNTIFS(Verdicts!$B$6:$B$80,"M",Verdicts!$J$6:$J$80,"<>") -> 2
A12: All chapters | B12: =SUM(B5:B11) -> 6 | C12: =SUM(C5:C11) -> 22 | D12: =SUM(D5:D11) -> 26 | E12: =SUM(E5:E11) -> 7 | F12: =SUM(F5:F11) -> 7 | G12: =SUM(G5:G11) -> 68 | H12: =SUM(H5:H11) -> 10 | I12: =SUM(I5:I11) -> 17
A14: Share of all claims
A15: Holds | B15: =B12/$G$12 -> 0.088235294
A16: Holds with new wording | B16: =C12/$G$12 -> 0.32352941
A17: Revise | B17: =D12/$G$12 -> 0.38235294
A18: Not supported | B18: =E12/$G$12 -> 0.10294118
A19: Not checked | B19: =F12/$G$12 -> 0.10294118
A21: Check: the claims of the inventory | B21: 68 | C21: =IF(B21=G12,"equal","check") -> equal
A23: The results the paper can lean on (robust tier of the step 4 workbook)
A24: Outcome | B24: AIPW | C24: OLS | D24: Romano-Wolf p | E24: Robustness value (5%) | F24: Reading
A25: Income from work (yes or no) | B25: 0.239 | C25: 0.297 | D25: 0.008 | E25: 0.117 | F25: 24 to 30 points more frequent among comparable towns households.
A26: Monthly spending per person (log) | B26: 0.627 | C26: 0.711 | D26: 0 | E26: 0.228 | F26: About 1.9 times as much per person in the towns.
A27: Refrigerator (yes or no) | B27: 0.298 | C27: 0.396 | D27: 0 | E27: 0.256 | F27: 30 to 40 points more towns households.
A28: Stove (yes or no) | B28: 0.437 | C28: 0.472 | D28: 0 | E28: 0.279 | F28: 44 to 47 points more towns households.
A29: Self-rated integration (1 to 10) | B29: -3.189 | C29: -3.139 | D29: 0 | E29: 0.287 | F29: About 3 points higher in the camp, among men and among women.
A30: Income fell since arrival (yes or no) | B30: -0.211 | C30: -0.253 | D30: 0.001 | E30: 0.161 | F30: 21 to 25 points fewer towns households report a fall.
A31: Used savings (yes or no) | B31: -0.218 | C31: -0.261 | D31: 0.012 | E31: 0.102 | F31: 22 to 26 points fewer towns households drew on savings.
A32: Source: encampment_design_diagnostics.xlsx, Verdict and Shocks verdict sheets (design 1, within the common support; Romano-Wolf within each family of outcomes). The Romano-Wolf p of 0 means below 0.0005.

Sheet Open items
A1: Matters that await a decision of the author
A3: Item | B3: What it is and what it would take
A4: Second blind reading of the protection of households across the materials (23 October 2026) | B4: A further instance read the corrected files with the same rule, checked each item of the first reading and read anew. The origins and places passed again: every cell keeps five possible values or more. Of the items of the first reading, most were closed and some only in part, and it found new routes. Corrected the same day: in the step 4 workbook, the R2 with controls and Rmax of the rows whose raw difference is withheld, which with the classical standard error gave the variance of a yes or no outcome and so its count, now withheld; in the step 3 workbook and in this sheet, the records of the first correction, which said more than the masks they explained, rewritten; in the step 3 workbook, section 2 of the Checks sheet, whose exact shares narrowed a cross of employment and work income, now in words; in the step 2 workbook, "almost no households in Amman", now "fewer than ten". Still open, for the next edition: the scales and the household size by subgroup in the step 3 workbook (Cuts measures, For whom and Figures sheets), whose means and standard deviations, printed to four decimals with the quartiles, give back the households at some answers; until that edition the step 3 workbook is not to be uploaded. The report stays in the record of the review and does not go to the repository.
A5: Blind reading of the protection of households across the materials (23 October 2026) | B5: A separate instance read, blind, the five workbooks, the Word version of this table, the technical note, the working paper and the brief, with one task: to find any count below ten households printed, or fixed or narrowed to fewer than three values by combining printed figures, in the records of the review and in the system of origins and places of interview. The origins and places passed: every cell keeps five possible values or more. It found twelve items of substance in other figures, all corrected the same day (the second reading, in the row above, found some closed only in part). In the step 4 workbook: the standard deviations, the raw differences, the R2 without controls and the Oster quantities of the eleven responses and of sickness, which with the means given the shock of the Decomposition sheet gave the masked cells of the towns households without the shock (and, for sickness, the households outside the support), now withheld, with the weighted MDD of sickness; the index means of the Health as a factor sheet and of block C of the Decomposition sheet that gave a masked item back, now withheld wherever one of their items is masked or withheld; two cells of block C that the step 3 workbook withholds; the index rows of block A, now with two decimals; and the Blind replication sheet, which still printed some of these. In the step 3 workbook: the households where the respondent reports no employment, which with the step 1 and step 2 workbooks fixed the number of women respondents who report employment, no longer printed; and further cells withheld where a masked cell kept too few possible counts. In the step 1 workbook and a step 3 record: the size of a group of households that report assistance only, no longer printed. In this table: row 5.6 printed the share of towns households naming some assistance, which the step 2 workbook withholds; it now reads nine in ten. Low items also corrected: the brief's "almost none in Amman" (now fewer than ten), its count of the places where the earlier page broke its own rule (now the seven of row M.8, among the ten flagged claims), the description of a withheld coefficient in the step 3 workbook, and the number of possible values stated for the map (five, not six). Two differences between figures of the earlier page and the review's (rows 0.2 and 1.4) come from coding the same households and describe no trait; they are left as they are, for the author's decision. The report stays in the record of the review and does not go to the repository.
